Workbook
Name CeilCond: 'قوائم الخامات والبنود والوحدات'!$O$4:$O$28
Name CeilMat: 'قوائم الخامات والبنود والوحدات'!$G$4:$G$28
Name CeilUnit: 'قوائم الخامات والبنود والوحدات'!$H$4:$H$28
Name CL_Gross: 'حصر الأسقف'!$M$4:$M$303
Name CL_Mat: 'حصر الأسقف'!$D$4:$D$303
Name CL_Net: 'حصر الأسقف'!$M$4:$M$303
Name CL_Space: 'حصر الأسقف'!$B$4:$B$303
Name CL_Status: 'حصر الأسقف'!$R$4:$R$303
Name CL_Unit: 'حصر الأسقف'!$O$4:$O$303
Name FL_Gross: 'حصر الأرضيات'!$K$4:$K$303
Name FL_Mat: 'حصر الأرضيات'!$D$4:$D$303
Name FL_Net: 'حصر الأرضيات'!$K$4:$K$303
Name FL_Space: 'حصر الأرضيات'!$B$4:$B$303
Name FL_Status: 'حصر الأرضيات'!$P$4:$P$303
Name FL_Unit: 'حصر الأرضيات'!$M$4:$M$303
Name FloorMat: 'قوائم الخامات والبنود والوحدات'!$A$4:$A$28
Name FloorUnit: 'قوائم الخامات والبنود والوحدات'!$B$4:$B$28
Name Levels: 'قوائم الخامات والبنود والوحدات'!$N$4:$N$28
Name LinMat: 'قوائم الخامات والبنود والوحدات'!$E$4:$E$28
Name LinUnit: 'قوائم الخامات والبنود والوحدات'!$F$4:$F$28
Name LN_Auto: 'حصر الوزرات والبنود الطولية'!$L$4:$L$303
Name LN_AutoEff: 'حصر الوزرات والبنود الطولية'!$V$4:$V$303
Name LN_Ded: 'حصر الوزرات والبنود الطولية'!$N$4:$N$303
Name LN_Gross: 'حصر الوزرات والبنود الطولية'!$J$4:$J$303
Name LN_Mat: 'حصر الوزرات والبنود الطولية'!$D$4:$D$303
Name LN_Net: 'حصر الوزرات والبنود الطولية'!$O$4:$O$303
Name LN_Space: 'حصر الوزرات والبنود الطولية'!$B$4:$B$303
Name LN_Status: 'حصر الوزرات والبنود الطولية'!$S$4:$S$303
Name LN_Unit: 'حصر الوزرات والبنود الطولية'!$P$4:$P$303
Name Method: 'قوائم الخامات والبنود والوحدات'!$Q$4:$Q$28
Name OP_AppFin: 'حصر الفتحات والخصومات'!$O$4:$O$303
Name OP_AppPl: 'حصر الفتحات والخصومات'!$P$4:$P$303
Name OP_AppSk: 'حصر الفتحات والخصومات'!$Q$4:$Q$303
Name OP_Area: 'حصر الفتحات والخصومات'!$J$4:$J$303
Name OP_Code: 'حصر الفتحات والخصومات'!$B$4:$B$303
Name OP_DedFin: 'حصر الفتحات والخصومات'!$K$4:$K$303
Name OP_DedPl: 'حصر الفتحات والخصومات'!$M$4:$M$303
Name OP_DedSk: 'حصر الفتحات والخصومات'!$N$4:$N$303
Name OP_Space: 'حصر الفتحات والخصومات'!$C$4:$C$303
Name OP_Status: 'حصر الفتحات والخصومات'!$T$4:$T$303
Name OP_Target: 'حصر الفتحات والخصومات'!$L$4:$L$303
Name OP_Wall: 'حصر الفتحات والخصومات'!$E$4:$E$303
Name OP_Wtot: 'حصر الفتحات والخصومات'!$U$4:$U$303
Name OpenTypes: 'قوائم الخامات والبنود والوحدات'!$K$4:$K$28
Name PL_Auto: 'حصر اللياسة والمحارة'!$J$4:$J$403
Name PL_Ded: 'حصر اللياسة والمحارة'!$L$4:$L$403
Name PL_FacesEff: 'حصر اللياسة والمحارة'!$T$4:$T$403
Name PL_Gross: 'حصر اللياسة والمحارة'!$I$4:$I$403
Name PL_Mat: 'حصر اللياسة والمحارة'!$E$4:$E$403
Name PL_Net: 'حصر اللياسة والمحارة'!$M$4:$M$403
Name PL_Space: 'حصر اللياسة والمحارة'!$B$4:$B$403
Name PL_Status: 'حصر اللياسة والمحارة'!$Q$4:$Q$403
Name PL_Unit: 'حصر اللياسة والمحارة'!$N$4:$N$403
Name PL_Wall: 'حصر اللياسة والمحارة'!$D$4:$D$403
Name PlMat: 'قوائم الخامات والبنود والوحدات'!$I$4:$I$28
Name PlUnit: 'قوائم الخامات والبنود والوحدات'!$J$4:$J$28
Name RoomNames: 'قوائم الخامات والبنود والوحدات'!$P$4:$P$28
Name SpaceCodes: 'سجل الفراغات'!$B$4:$B$153
Name SpaceLevels: 'سجل الفراغات'!$D$4:$D$153
Name SpaceNames: 'سجل الفراغات'!$C$4:$C$153

Sheet تعليمات الاستخدام
A1: تعليمات استخدام ملف حصر كميات التشطيبات (Quantity Takeoff & BOQ)
A3: دلالة الألوان
B4: خلايا صفراء فاتحة = خلايا إدخال (اكتب أو اختر من القائمة المنسدلة).
B5: خلايا زرقاء فاتحة = معادلات تلقائية (مقفلة — لا تكتب فيها).
B6: الصف الثاني في كل ورقة حصر = إجمالي الصفوف الظاهرة بعد الفلتر، لوحدة واحدة فقط (لا تُجمع وحدات مختلفة).
A7: ترتيب العمل
A8: 1 | B8: املأ ورقة «بيانات المشروع».
A9: 2 | B9: سجّل كل غرفة/فراغ في «سجل الفراغات» بكود فريد (مثال: G-01 للدور الأرضي). الكود هو مفتاح الربط بين كل الأوراق.
A10: 3 | B10: راجع ورقة «القوائم»: أضف أي خامة أو بند جديد في الخانات الصفراء الفارغة مع وحدته، فيظهر تلقائيًا في القوائم المنسدلة والملخصات. تجنب الرمزين * و ? في أسماء الخامات (استخدم × بدلًا من *).
A11: 4 | B11: الأرضيات والأسقف: صف لكل جزء. أدخل الطول × العرض × التكرار، أو أدخل «المساحة المباشرة» المقاسة على الطبيعة (تُقدَّم على الأبعاد وتُضرب في التكرار؛ التكرار الفارغ = 1). الغرفة غير المنتظمة تُقسَّم إلى عدة صفوف بنفس كود الفراغ والخامة، وعمود «إجمالي الفراغ لنفس الخامة» يجمعها.
A12: 5 | B12: الحوائط: صف مستقل لكل حائط أو قطاع حائط بكود حائط (W1, W2 ...). المساحة تُحسب تلقائيًا = الطول × الارتفاع × التكرار. لإدخال مساحة مقاسة مباشرة اختر «يدوي» في عمود «طريقة الحساب» ثم اكتبها في «المساحة المباشرة» (لا تُستخدم مع «تلقائي»). إذا كان على الحائط أكثر من خامة (سيراميك سفلي + دهان علوي) فسجّل كل خامة في صف مستقل بنفس كود الحائط وبأبعادها الفعلية. عمود «خصم الفتحات من هذا السجل؟» = «لا» يوقف خصم الفتحات عن هذا السجل حسب طريقة الحصر المعتمدة.
A13: 6 | B13: الفتحات: صف لكل فتحة بكود فريد، مع كود الفراغ وكود الحائط الواقعة عليه. حدّد بوضوح (نعم/لا) هل تُخصم من: تشطيب الحوائط / اللياسة / الوزرات. الخانة الفارغة = لا تُخصم.
A14: 7 | B14: الوزرات والبنود الطولية: أدخل الطول المقاس مباشرة (أو محيط الفراغ)، أو أدخل طول وعرض الفراغ ليُحسب المحيط = 2×(الطول+العرض). اختر «نعم» في عمود الخصم التلقائي ليُخصم عرض الفتحات المحدد لها «خصم من الوزرات = نعم» في نفس الفراغ.
A15: 8 | B15: اللياسة والمحارة: صف لكل حائط مع عدد الأوجه (فارغ = 1). خصم الفتحة = مساحتها × عدد الأوجه.
A16: 9 | B16: راجع عمود «الحالة» في كل ورقة ثم الملخصين. استخدم الفلاتر في صف العناوين للبحث والتصفية.
A17: قواعد الخصم (لمنع تكرار الخصم)
A18: • | B18: الفتحة تُخصم من الحائط المطابق لها في كود الفراغ وكود الحائط معًا فقط، ولا تؤثر على الأرضيات أو الأسقف أو أي حائط آخر.
A19: • | B19: إذا كان للحائط سجل تشطيب واحد تُخصم منه الفتحة مباشرة. إذا كان له أكثر من خامة فيجب اختيار «الخامة المخصوم منها» في سجل الفتحة، وإلا لا تُخصم ويظهر تنبيه. الفتحة الممتدة على خامتين تُسجَّل كجزأين بكودين (مثال: D1-a و D1-b) بارتفاع كل جزء.
A20: • | B20: النوافذ لا تُخصم من الوزرات إلا إذا اخترت «نعم» صراحةً في عمود «خصم من الوزرات». الخصم التلقائي للوزرات يُطبَّق على أول سجل فقط في كل فراغ؛ وأي سجل آخر يُستخدم له «خصومات أخرى (يدوي)».
A21: • | B21: أعمدة «مخصوم فعليًا» في ورقة الفتحات تبيّن أين طُبِّق الخصم. وفحوص التطابق في ورقة ملخص البند والخامة تتأكد أن مجموع الخصومات = مجموع المخصوم فعليًا.
A22: منع التكرار
A23: • | B23: الصف المكرر (نفس الفراغ والخامة والوصف والأبعاد في الأرضيات/الأسقف/البنود الطولية، أو نفس الفراغ وكود الحائط والخامة في الحوائط/اللياسة، أو نفس كود الفتحة) لا يُحتسب وتظهر حالته «تكرار — غير محتسب». للأجزاء المتماثلة استخدم «عدد التكرارات» أو وصفًا مختلفًا.
A24: • | B24: للأجزاء المتداخلة: اختر «لا» في عمود «يُحتسب؟» لاستبعاد الجزء دون حذفه، واكتب السبب في الملاحظات، أو اختر «نعم» في «يحتاج مراجعة؟».
A25: حالات السجل
A26: • | B26: مكتمل / ناقص قياس / ناقص بيانات / يحتاج مراجعة / تكرار — غير محتسب / تنبيه خصم / خطأ خصم / مستبعد من الحصر. عدد السجلات غير المكتملة يظهر أعلى كل ورقة وفي الملخصات.
A27: الأسعار (اختياري)
A28: • | B28: في ورقة «ملخص الكميات حسب البند والخامة» أدخل سعر الوحدة لأي خامة ليُحسب إجمالي التكلفة. ترك السعر فارغًا لا يؤثر على الحصر الكمي.
A29: ملاحظات عامة
A30: • | B30: أوراق الحصر محمية بدون كلمة مرور لحماية المعادلات فقط. لإلغاء الحماية: مراجعة ← إلغاء حماية الورقة.
A31: • | B31: ورقة «مثال توضيحي» منفصلة تمامًا ولا تدخل في أي إجمالي. أوراق الحصر فارغة ولا تحتوي أي كميات افتراضية.
A32: • | B32: كل الأبعاد بالمتر. الصفوف المجهزة: 150 فراغًا، 300 صف للأرضيات/الفتحات/البنود الطولية/الأسقف، 400 صف للحوائط/اللياسة.

Sheet بيانات المشروع
A1: بيانات المشروع
A3: اسم المشروع
A4: المالك / العميل
A5: الموقع
A6: تاريخ الحصر
A7: القائم بالحصر
A8: المراجع / المعتمد
A9: طريقة الحصر
A10: رقم الإصدار / المراجعة
A11: العملة (للأسعار الاختيارية)
A12: ملاحظات عامة

Sheet سجل الفراغات
A1: سجل الفراغات — كود واسم كل غرفة أو فراغ
A2: ="عدد الفراغات المسجلة: "&COUNTA(B4:B153) -> عدد الفراغات المسجلة: 0
A3: م | B3: كود الفراغ (فريد) | C3: اسم الفراغ | D3: الدور | E3: ملاحظات | F3: الحالة
A4: 1 | F4: =IF(COUNTA(B4:E4)=0,"",IF(B4="","ناقص: الكود",IF(COUNTIF(SpaceCodes,B4)>1,"كود مكرر",IF(C4="","ناقص: الاسم","مسجل"))))
A5: 2 | F5: =IF(COUNTA(B5:E5)=0,"",IF(B5="","ناقص: الكود",IF(COUNTIF(SpaceCodes,B5)>1,"كود مكرر",IF(C5="","ناقص: الاسم","مسجل"))))
A6: 3 | F6: =IF(COUNTA(B6:E6)=0,"",IF(B6="","ناقص: الكود",IF(COUNTIF(SpaceCodes,B6)>1,"كود مكرر",IF(C6="","ناقص: الاسم","مسجل"))))
A7: 4 | F7: =IF(COUNTA(B7:E7)=0,"",IF(B7="","ناقص: الكود",IF(COUNTIF(SpaceCodes,B7)>1,"كود مكرر",IF(C7="","ناقص: الاسم","مسجل"))))
A8: 5 | F8: =IF(COUNTA(B8:E8)=0,"",IF(B8="","ناقص: الكود",IF(COUNTIF(SpaceCodes,B8)>1,"كود مكرر",IF(C8="","ناقص: الاسم","مسجل"))))
A9: 6 | F9: =IF(COUNTA(B9:E9)=0,"",IF(B9="","ناقص: الكود",IF(COUNTIF(SpaceCodes,B9)>1,"كود مكرر",IF(C9="","ناقص: الاسم","مسجل"))))
A10: 7 | F10: =IF(COUNTA(B10:E10)=0,"",IF(B10="","ناقص: الكود",IF(COUNTIF(SpaceCodes,B10)>1,"كود مكرر",IF(C10="","ناقص: الاسم","مسجل"))))
A11: 8 | F11: =IF(COUNTA(B11:E11)=0,"",IF(B11="","ناقص: الكود",IF(COUNTIF(SpaceCodes,B11)>1,"كود مكرر",IF(C11="","ناقص: الاسم","مسجل"))))
A12: 9 | F12: =IF(COUNTA(B12:E12)=0,"",IF(B12="","ناقص: الكود",IF(COUNTIF(SpaceCodes,B12)>1,"كود مكرر",IF(C12="","ناقص: الاسم","مسجل"))))
A13: 10 | F13: =IF(COUNTA(B13:E13)=0,"",IF(B13="","ناقص: الكود",IF(COUNTIF(SpaceCodes,B13)>1,"كود مكرر",IF(C13="","ناقص: الاسم","مسجل"))))
A14: 11 | F14: =IF(COUNTA(B14:E14)=0,"",IF(B14="","ناقص: الكود",IF(COUNTIF(SpaceCodes,B14)>1,"كود مكرر",IF(C14="","ناقص: الاسم","مسجل"))))
A15: 12 | F15: =IF(COUNTA(B15:E15)=0,"",IF(B15="","ناقص: الكود",IF(COUNTIF(SpaceCodes,B15)>1,"كود مكرر",IF(C15="","ناقص: الاسم","مسجل"))))
... A153: 150 | F153: =IF(COUNTA(B153:E153)=0,"",IF(B153="","ناقص: الكود",IF(COUNTIF(SpaceCodes,B153)>1,"كود مكرر",IF(C153="","ناقص: الاسم","مسجل"))))

Sheet حصر الأرضيات
A1: حصر الأرضيات — صف لكل جزء من أرضية الفراغ (الوحدة الأساسية: م²)
A2: إجمالي الصفوف الظاهرة بعد الفلتر (م² فقط) ← | K2: =SUMPRODUCT(SUBTOTAL(109,OFFSET(K$4,ROW(K$4:K$303)-ROW(K$4),0)),--(M$4:M$303="م²")) -> 0 | P2: ="غير مكتمل: "&(COUNTIF(P$4:P$303,"?*")-COUNTIF(P$4:P$303,"مكتمل")) -> غير مكتمل: 0
A3: م | B3: كود الفراغ | C3: اسم الفراغ | D3: نوع الخامة | E3: وصف الجزء | F3: الطول (م) | G3: العرض (م) | H3: عدد التكرارات (فارغ = 1) | I3: المساحة المباشرة (اختياري) | J3: يُحتسب؟ (فارغ = نعم) | K3: المساحة المحسوبة | L3: إجمالي الفراغ لنفس الخامة | M3: الوحدة | N3: يحتاج مراجعة؟ | O3: ملاحظات | P3: الحالة | Q3: مفتاح | R3: تكرار
A4: 1 | C4: =IF(B4="","",IFERROR(INDEX(SpaceNames,MATCH(B4,SpaceCodes,0))&"","")) | K4: =IF(Q4="","",IF(OR(J4="لا",R4=1),0,IF(I4<>"",I4*IF(H4="",1,H4),IF(AND(F4<>"",G4<>""),F4*G4*IF(H4="",1,H4),"")))) | L4: =IF(OR(Q4="",B4="",D4=""),"",SUMIFS(FL_Net,FL_Space,B4,FL_Mat,D4)) | M4: =IF(D4="","",IFERROR(IF(INDEX(FloorUnit,MATCH(D4,FloorMat,0))="","م²",INDEX(FloorUnit,MATCH(D4,FloorMat,0))),"م²")) | P4: =IF(Q4="","",IF(R4=1,"تكرار — غير محتسب",IF(B4="","ناقص بيانات: كود الفراغ",IF(COUNTIF(SpaceCodes,B4)=0,"ناقص بيانات: الفراغ غير مسجل",IF(D4="","ناقص بيانات: الخامة",IF(AND(I4="",OR(F4="",G4="")),"ناقص قياس",IF(J4="لا","مستبعد من الحصر",IF(N4="نعم","يحتاج مراجعة","مكتمل")))))))) | Q4: =IF(COUNTA(B4,D4:I4)=0,"",B4&"|"&D4&"|"&E4&"|"&F4&"|"&G4&"|"&I4) | R4: =IF(Q4="",0,IF(SUMPRODUCT(--(Q$4:Q4=Q4))>1,1,0)) -> 0
A5: 2 | C5: =IF(B5="","",IFERROR(INDEX(SpaceNames,MATCH(B5,SpaceCodes,0))&"","")) | K5: =IF(Q5="","",IF(OR(J5="لا",R5=1),0,IF(I5<>"",I5*IF(H5="",1,H5),IF(AND(F5<>"",G5<>""),F5*G5*IF(H5="",1,H5),"")))) | L5: =IF(OR(Q5="",B5="",D5=""),"",SUMIFS(FL_Net,FL_Space,B5,FL_Mat,D5)) | M5: =IF(D5="","",IFERROR(IF(INDEX(FloorUnit,MATCH(D5,FloorMat,0))="","م²",INDEX(FloorUnit,MATCH(D5,FloorMat,0))),"م²")) | P5: =IF(Q5="","",IF(R5=1,"تكرار — غير محتسب",IF(B5="","ناقص بيانات: كود الفراغ",IF(COUNTIF(SpaceCodes,B5)=0,"ناقص بيانات: الفراغ غير مسجل",IF(D5="","ناقص بيانات: الخامة",IF(AND(I5="",OR(F5="",G5="")),"ناقص قياس",IF(J5="لا","مستبعد من الحصر",IF(N5="نعم","يحتاج مراجعة","مكتمل")))))))) | Q5: =IF(COUNTA(B5,D5:I5)=0,"",B5&"|"&D5&"|"&E5&"|"&F5&"|"&G5&"|"&I5) | R5: =IF(Q5="",0,IF(SUMPRODUCT(--(Q$4:Q5=Q5))>1,1,0)) -> 0
A6: 3 | C6: =IF(B6="","",IFERROR(INDEX(SpaceNames,MATCH(B6,SpaceCodes,0))&"","")) | K6: =IF(Q6="","",IF(OR(J6="لا",R6=1),0,IF(I6<>"",I6*IF(H6="",1,H6),IF(AND(F6<>"",G6<>""),F6*G6*IF(H6="",1,H6),"")))) | L6: =IF(OR(Q6="",B6="",D6=""),"",SUMIFS(FL_Net,FL_Space,B6,FL_Mat,D6)) | M6: =IF(D6="","",IFERROR(IF(INDEX(FloorUnit,MATCH(D6,FloorMat,0))="","م²",INDEX(FloorUnit,MATCH(D6,FloorMat,0))),"م²")) | P6: =IF(Q6="","",IF(R6=1,"تكرار — غير محتسب",IF(B6="","ناقص بيانات: كود الفراغ",IF(COUNTIF(SpaceCodes,B6)=0,"ناقص بيانات: الفراغ غير مسجل",IF(D6="","ناقص بيانات: الخامة",IF(AND(I6="",OR(F6="",G6="")),"ناقص قياس",IF(J6="لا","مستبعد من الحصر",IF(N6="نعم","يحتاج مراجعة","مكتمل")))))))) | Q6: =IF(COUNTA(B6,D6:I6)=0,"",B6&"|"&D6&"|"&E6&"|"&F6&"|"&G6&"|"&I6) | R6: =IF(Q6="",0,IF(SUMPRODUCT(--(Q$4:Q6=Q6))>1,1,0)) -> 0
A7: 4 | C7: =IF(B7="","",IFERROR(INDEX(SpaceNames,MATCH(B7,SpaceCodes,0))&"","")) | K7: =IF(Q7="","",IF(OR(J7="لا",R7=1),0,IF(I7<>"",I7*IF(H7="",1,H7),IF(AND(F7<>"",G7<>""),F7*G7*IF(H7="",1,H7),"")))) | L7: =IF(OR(Q7="",B7="",D7=""),"",SUMIFS(FL_Net,FL_Space,B7,FL_Mat,D7)) | M7: =IF(D7="","",IFERROR(IF(INDEX(FloorUnit,MATCH(D7,FloorMat,0))="","م²",INDEX(FloorUnit,MATCH(D7,FloorMat,0))),"م²")) | P7: =IF(Q7="","",IF(R7=1,"تكرار — غير محتسب",IF(B7="","ناقص بيانات: كود الفراغ",IF(COUNTIF(SpaceCodes,B7)=0,"ناقص بيانات: الفراغ غير مسجل",IF(D7="","ناقص بيانات: الخامة",IF(AND(I7="",OR(F7="",G7="")),"ناقص قياس",IF(J7="لا","مستبعد من الحصر",IF(N7="نعم","يحتاج مراجعة","مكتمل")))))))) | Q7: =IF(COUNTA(B7,D7:I7)=0,"",B7&"|"&D7&"|"&E7&"|"&F7&"|"&G7&"|"&I7) | R7: =IF(Q7="",0,IF(SUMPRODUCT(--(Q$4:Q7=Q7))>1,1,0)) -> 0
A8: 5 | C8: =IF(B8="","",IFERROR(INDEX(SpaceNames,MATCH(B8,SpaceCodes,0))&"","")) | K8: =IF(Q8="","",IF(OR(J8="لا",R8=1),0,IF(I8<>"",I8*IF(H8="",1,H8),IF(AND(F8<>"",G8<>""),F8*G8*IF(H8="",1,H8),"")))) | L8: =IF(OR(Q8="",B8="",D8=""),"",SUMIFS(FL_Net,FL_Space,B8,FL_Mat,D8)) | M8: =IF(D8="","",IFERROR(IF(INDEX(FloorUnit,MATCH(D8,FloorMat,0))="","م²",INDEX(FloorUnit,MATCH(D8,FloorMat,0))),"م²")) | P8: =IF(Q8="","",IF(R8=1,"تكرار — غير محتسب",IF(B8="","ناقص بيانات: كود الفراغ",IF(COUNTIF(SpaceCodes,B8)=0,"ناقص بيانات: الفراغ غير مسجل",IF(D8="","ناقص بيانات: الخامة",IF(AND(I8="",OR(F8="",G8="")),"ناقص قياس",IF(J8="لا","مستبعد من الحصر",IF(N8="نعم","يحتاج مراجعة","مكتمل")))))))) | Q8: =IF(COUNTA(B8,D8:I8)=0,"",B8&"|"&D8&"|"&E8&"|"&F8&"|"&G8&"|"&I8) | R8: =IF(Q8="",0,IF(SUMPRODUCT(--(Q$4:Q8=Q8))>1,1,0)) -> 0
A9: 6 | C9: =IF(B9="","",IFERROR(INDEX(SpaceNames,MATCH(B9,SpaceCodes,0))&"","")) | K9: =IF(Q9="","",IF(OR(J9="لا",R9=1),0,IF(I9<>"",I9*IF(H9="",1,H9),IF(AND(F9<>"",G9<>""),F9*G9*IF(H9="",1,H9),"")))) | L9: =IF(OR(Q9="",B9="",D9=""),"",SUMIFS(FL_Net,FL_Space,B9,FL_Mat,D9)) | M9: =IF(D9="","",IFERROR(IF(INDEX(FloorUnit,MATCH(D9,FloorMat,0))="","م²",INDEX(FloorUnit,MATCH(D9,FloorMat,0))),"م²")) | P9: =IF(Q9="","",IF(R9=1,"تكرار — غير محتسب",IF(B9="","ناقص بيانات: كود الفراغ",IF(COUNTIF(SpaceCodes,B9)=0,"ناقص بيانات: الفراغ غير مسجل",IF(D9="","ناقص بيانات: الخامة",IF(AND(I9="",OR(F9="",G9="")),"ناقص قياس",IF(J9="لا","مستبعد من الحصر",IF(N9="نعم","يحتاج مراجعة","مكتمل")))))))) | Q9: =IF(COUNTA(B9,D9:I9)=0,"",B9&"|"&D9&"|"&E9&"|"&F9&"|"&G9&"|"&I9) | R9: =IF(Q9="",0,IF(SUMPRODUCT(--(Q$4:Q9=Q9))>1,1,0)) -> 0
A10: 7 | C10: =IF(B10="","",IFERROR(INDEX(SpaceNames,MATCH(B10,SpaceCodes,0))&"","")) | K10: =IF(Q10="","",IF(OR(J10="لا",R10=1),0,IF(I10<>"",I10*IF(H10="",1,H10),IF(AND(F10<>"",G10<>""),F10*G10*IF(H10="",1,H10),"")))) | L10: =IF(OR(Q10="",B10="",D10=""),"",SUMIFS(FL_Net,FL_Space,B10,FL_Mat,D10)) | M10: =IF(D10="","",IFERROR(IF(INDEX(FloorUnit,MATCH(D10,FloorMat,0))="","م²",INDEX(FloorUnit,MATCH(D10,FloorMat,0))),"م²")) | P10: =IF(Q10="","",IF(R10=1,"تكرار — غير محتسب",IF(B10="","ناقص بيانات: كود الفراغ",IF(COUNTIF(SpaceCodes,B10)=0,"ناقص بيانات: الفراغ غير مسجل",IF(D10="","ناقص بيانات: الخامة",IF(AND(I10="",OR(F10="",G10="")),"ناقص قياس",IF(J10="لا","مستبعد من الحصر",IF(N10="نعم","يحتاج مراجعة","مكتمل")))))))) | Q10: =IF(COUNTA(B10,D10:I10)=0,"",B10&"|"&D10&"|"&E10&"|"&F10&"|"&G10&"|"&I10) | R10: =IF(Q10="",0,IF(SUMPRODUCT(--(Q$4:Q10=Q10))>1,1,0)) -> 0
A11: 8 | C11: =IF(B11="","",IFERROR(INDEX(SpaceNames,MATCH(B11,SpaceCodes,0))&"","")) | K11: =IF(Q11="","",IF(OR(J11="لا",R11=1),0,IF(I11<>"",I11*IF(H11="",1,H11),IF(AND(F11<>"",G11<>""),F11*G11*IF(H11="",1,H11),"")))) | L11: =IF(OR(Q11="",B11="",D11=""),"",SUMIFS(FL_Net,FL_Space,B11,FL_Mat,D11)) | M11: =IF(D11="","",IFERROR(IF(INDEX(FloorUnit,MATCH(D11,FloorMat,0))="","م²",INDEX(FloorUnit,MATCH(D11,FloorMat,0))),"م²")) | P11: =IF(Q11="","",IF(R11=1,"تكرار — غير محتسب",IF(B11="","ناقص بيانات: كود الفراغ",IF(COUNTIF(SpaceCodes,B11)=0,"ناقص بيانات: الفراغ غير مسجل",IF(D11="","ناقص بيانات: الخامة",IF(AND(I11="",OR(F11="",G11="")),"ناقص قياس",IF(J11="لا","مستبعد من الحصر",IF(N11="نعم","يحتاج مراجعة","مكتمل")))))))) | Q11: =IF(COUNTA(B11,D11:I11)=0,"",B11&"|"&D11&"|"&E11&"|"&F11&"|"&G11&"|"&I11) | R11: =IF(Q11="",0,IF(SUMPRODUCT(--(Q$4:Q11=Q11))>1,1,0)) -> 0
A12: 9 | C12: =IF(B12="","",IFERROR(INDEX(SpaceNames,MATCH(B12,SpaceCodes,0))&"","")) | K12: =IF(Q12="","",IF(OR(J12="لا",R12=1),0,IF(I12<>"",I12*IF(H12="",1,H12),IF(AND(F12<>"",G12<>""),F12*G12*IF(H12="",1,H12),"")))) | L12: =IF(OR(Q12="",B12="",D12=""),"",SUMIFS(FL_Net,FL_Space,B12,FL_Mat,D12)) | M12: =IF(D12="","",IFERROR(IF(INDEX(FloorUnit,MATCH(D12,FloorMat,0))="","م²",INDEX(FloorUnit,MATCH(D12,FloorMat,0))),"م²")) | P12: =IF(Q12="","",IF(R12=1,"تكرار — غير محتسب",IF(B12="","ناقص بيانات: كود الفراغ",IF(COUNTIF(SpaceCodes,B12)=0,"ناقص بيانات: الفراغ غير مسجل",IF(D12="","ناقص بيانات: الخامة",IF(AND(I12="",OR(F12="",G12="")),"ناقص قياس",IF(J12="لا","مستبعد من الحصر",IF(N12="نعم","يحتاج مراجعة","مكتمل")))))))) | Q12: =IF(COUNTA(B12,D12:I12)=0,"",B12&"|"&D12&"|"&E12&"|"&F12&"|"&G12&"|"&I12) | R12: =IF(Q12="",0,IF(SUMPRODUCT(--(Q$4:Q12=Q12))>1,1,0)) -> 0
A13: 10 | C13: =IF(B13="","",IFERROR(INDEX(SpaceNames,MATCH(B13,SpaceCodes,0))&"","")) | K13: =IF(Q13="","",IF(OR(J13="لا",R13=1),0,IF(I13<>"",I13*IF(H13="",1,H13),IF(AND(F13<>"",G13<>""),F13*G13*IF(H13="",1,H13),"")))) | L13: =IF(OR(Q13="",B13="",D13=""),"",SUMIFS(FL_Net,FL_Space,B13,FL_Mat,D13)) | M13: =IF(D13="","",IFERROR(IF(INDEX(FloorUnit,MATCH(D13,FloorMat,0))="","م²",INDEX(FloorUnit,MATCH(D13,FloorMat,0))),"م²")) | P13: =IF(Q13="","",IF(R13=1,"تكرار — غير محتسب",IF(B13="","ناقص بيانات: كود الفراغ",IF(COUNTIF(SpaceCodes,B13)=0,"ناقص بيانات: الفراغ غير مسجل",IF(D13="","ناقص بيانات: الخامة",IF(AND(I13="",OR(F13="",G13="")),"ناقص قياس",IF(J13="لا","مستبعد من الحصر",IF(N13="نعم","يحتاج مراجعة","مكتمل")))))))) | Q13: =IF(COUNTA(B13,D13:I13)=0,"",B13&"|"&D13&"|"&E13&"|"&F13&"|"&G13&"|"&I13) | R13: =IF(Q13="",0,IF(SUMPRODUCT(--(Q$4:Q13=Q13))>1,1,0)) -> 0
A14: 11 | C14: =IF(B14="","",IFERROR(INDEX(SpaceNames,MATCH(B14,SpaceCodes,0))&"","")) | K14: =IF(Q14="","",IF(OR(J14="لا",R14=1),0,IF(I14<>"",I14*IF(H14="",1,H14),IF(AND(F14<>"",G14<>""),F14*G14*IF(H14="",1,H14),"")))) | L14: =IF(OR(Q14="",B14="",D14=""),"",SUMIFS(FL_Net,FL_Space,B14,FL_Mat,D14)) | M14: =IF(D14="","",IFERROR(IF(INDEX(FloorUnit,MATCH(D14,FloorMat,0))="","م²",INDEX(FloorUnit,MATCH(D14,FloorMat,0))),"م²")) | P14: =IF(Q14="","",IF(R14=1,"تكرار — غير محتسب",IF(B14="","ناقص بيانات: كود الفراغ",IF(COUNTIF(SpaceCodes,B14)=0,"ناقص بيانات: الفراغ غير مسجل",IF(D14="","ناقص بيانات: الخامة",IF(AND(I14="",OR(F14="",G14="")),"ناقص قياس",IF(J14="لا","مستبعد من الحصر",IF(N14="نعم","يحتاج مراجعة","مكتمل")))))))) | Q14: =IF(COUNTA(B14,D14:I14)=0,"",B14&"|"&D14&"|"&E14&"|"&F14&"|"&G14&"|"&I14) | R14: =IF(Q14="",0,IF(SUMPRODUCT(--(Q$4:Q14=Q14))>1,1,0)) -> 0
A15: 12 | C15: =IF(B15="","",IFERROR(INDEX(SpaceNames,MATCH(B15,SpaceCodes,0))&"","")) | K15: =IF(Q15="","",IF(OR(J15="لا",R15=1),0,IF(I15<>"",I15*IF(H15="",1,H15),IF(AND(F15<>"",G15<>""),F15*G15*IF(H15="",1,H15),"")))) | L15: =IF(OR(Q15="",B15="",D15=""),"",SUMIFS(FL_Net,FL_Space,B15,FL_Mat,D15)) | M15: =IF(D15="","",IFERROR(IF(INDEX(FloorUnit,MATCH(D15,FloorMat,0))="","م²",INDEX(FloorUnit,MATCH(D15,FloorMat,0))),"م²")) | P15: =IF(Q15="","",IF(R15=1,"تكرار — غير محتسب",IF(B15="","ناقص بيانات: كود الفراغ",IF(COUNTIF(SpaceCodes,B15)=0,"ناقص بيانات: الفراغ غير مسجل",IF(D15="","ناقص بيانات: الخامة",IF(AND(I15="",OR(F15="",G15="")),"ناقص قياس",IF(J15="لا","مستبعد من الحصر",IF(N15="نعم","يحتاج مراجعة","مكتمل")))))))) | Q15: =IF(COUNTA(B15,D15:I15)=0,"",B15&"|"&D15&"|"&E15&"|"&F15&"|"&G15&"|"&I15) | R15: =IF(Q15="",0,IF(SUMPRODUCT(--(Q$4:Q15=Q15))>1,1,0)) -> 0
... A303: 300 | C303: =IF(B303="","",IFERROR(INDEX(SpaceNames,MATCH(B303,SpaceCodes,0))&"","")) | K303: =IF(Q303="","",IF(OR(J303="لا",R303=1),0,IF(I303<>"",I303*IF(H303="",1,H303),IF(AND(F303<>"",G303<>""),F303*G303*IF(H303="",1,H303),"")))) | L303: =IF(OR(Q303="",B303="",D303=""),"",SUMIFS(FL_Net,FL_Space,B303,FL_Mat,D303)) | M303: =IF(D303="","",IFERROR(IF(INDEX(FloorUnit,MATCH(D303,FloorMat,0))="","م²",INDEX(FloorUnit,MATCH(D303,FloorMat,0))),"م²")) | P303: =IF(Q303="","",IF(R303=1,"تكرار — غير محتسب",IF(B303="","ناقص بيانات: كود الفراغ",IF(COUNTIF(SpaceCodes,B303)=0,"ناقص بيانات: الفراغ غير مسجل",IF(D303="","ناقص بيانات: الخامة",IF(AND(I303="",OR(F303="",G303="")),"ناقص قياس",IF(J303="لا","مستبعد من الحصر",IF(N303="نعم","يحتاج مراجعة","مكتمل")))))))) | Q303: =IF(COUNTA(B303,D303:I303)=0,"",B303&"|"&D303&"|"&E303&"|"&F303&"|"&G303&"|"&I303) | R303: =IF(Q303="",0,IF(SUMPRODUCT(--(Q$4:Q303=Q303))>1,1,0)) -> 0

Sheet حصر الحوائط والتشطيبات الرأسية
A1: حصر الحوائط والتشطيبات الرأسية — صف لكل حائط/قطاع ولكل خامة
A2: إجمالي الصفوف الظاهرة بعد الفلتر (م² فقط) ← | K2: =SUMPRODUCT(SUBTOTAL(109,OFFSET(K$4,ROW(K$4:K$403)-ROW(K$4),0)),--(Q$4:Q$403="م²")) -> 0 | O2: =SUMPRODUCT(SUBTOTAL(109,OFFSET(O$4,ROW(O$4:O$403)-ROW(O$4),0)),--(Q$4:Q$403="م²")) -> 0 | P2: =SUMPRODUCT(SUBTOTAL(109,OFFSET(P$4,ROW(P$4:P$403)-ROW(P$4),0)),--(Q$4:Q$403="م²")) -> 0 | T2: ="غير مكتمل: "&(COUNTIF(T$4:T$403,"?*")-COUNTIF(T$4:T$403,"مكتمل")) -> غير مكتمل: 0
A3: م | B3: كود الفراغ | C3: اسم الفراغ | D3: كود الحائط أو القطاع | E3: نوع الخامة / التشطيب | F3: طول الحائط (م) | G3: ارتفاع التشطيب (م) | H3: عدد التكرارات (فارغ = 1) | I3: طريقة الحساب (فارغ = تلقائي) | J3: المساحة المباشرة (للطريقة اليدوية) | K3: المساحة الإجمالية (محسوبة) | L3: خصم الفتحات من هذا السجل؟ (فارغ = نعم) | M3: خصم فتحات هذا الحائط (تلقائي) | N3: خصومات أخرى (يدوي) | O3: إجمالي الخصومات | P3: المساحة الصافية | Q3: الوحدة | R3: يحتاج مراجعة؟ | S3: ملاحظات | T3: الحالة | U3: مفتاح | V3: تكرار | W3: عدد سجلات الحائط | X3: الخصم مفعل
A4: 1 | C4: =IF(B4="","",IFERROR(INDEX(SpaceNames,MATCH(B4,SpaceCodes,0))&"","")) | K4: =IF(U4="","",IF(V4=1,0,IF(I4="يدوي",IF(J4<>"",J4*IF(H4="",1,H4),""),IF(AND(F4<>"",G4<>""),F4*G4*IF(H4="",1,H4),"")))) | M4: =IF(U4="","",IF(OR(X4=0,B4="",D4=""),0,IF(E4="",0,SUMIFS(OP_Area,OP_Space,B4,OP_Wall,D4,OP_DedFin,"نعم",OP_Target,E4))+IF(W4=1,SUMIFS(OP_Area,OP_Space,B4,OP_Wall,D4,OP_DedFin,"نعم",OP_Target,""),0))) | O4: =IF(OR(U4="",K4=""),"",N(M4)+N(N4)) | P4: =IF(OR(U4="",K4=""),"",K4-O4) | Q4: =IF(E4="","",IFERROR(IF(INDEX(WallUnit,MATCH(E4,WallMat,0))="","م²",INDEX(WallUnit,MATCH(E4,WallMat,0))),"م²")) | T4: =IF(U4="","",IF(V4=1,"تكرار — غير محتسب",IF(B4="","ناقص بيانات: كود الفراغ",IF(COUNTIF(SpaceCodes,B4)=0,"ناقص بيانات: الفراغ غير مسجل",IF(D4="","ناقص بيانات: كود الحائط",IF(E4="","ناقص بيانات: الخامة",IF(AND(K4="",I4="يدوي"),"ناقص قياس: أدخل المساحة المباشرة",IF(AND(K4="",J4<>""),"ناقص قياس: اختر «يدوي» أو أدخل الطول والارتفاع",IF(K4="","ناقص قياس",IF(O4>K4+0.000001,"خطأ خصم: الخصم أكبر من الإجمالي",IF(R4="نعم","يحتاج مراجعة","مكتمل"))))))))))) | U4: =IF(COUNTA(B4,D4:J4,N4)=0,"",B4&"|"&D4&"|"&E4) | V4: =IF(OR(U4="",D4=""),0,IF(SUMPRODUCT(--(U$4:U4=U4))>1,1,0)) -> 0 | W4: =IF(OR(U4="",B4="",D4=""),0,COUNTIFS(WL_Space,B4,WL_Wall,D4,WL_Dup,0)) -> 0 | X4: =IF(OR(U4="",V4=1,L4="لا"),0,1) -> 0
A5: 2 | C5: =IF(B5="","",IFERROR(INDEX(SpaceNames,MATCH(B5,SpaceCodes,0))&"","")) | K5: =IF(U5="","",IF(V5=1,0,IF(I5="يدوي",IF(J5<>"",J5*IF(H5="",1,H5),""),IF(AND(F5<>"",G5<>""),F5*G5*IF(H5="",1,H5),"")))) | M5: =IF(U5="","",IF(OR(X5=0,B5="",D5=""),0,IF(E5="",0,SUMIFS(OP_Area,OP_Space,B5,OP_Wall,D5,OP_DedFin,"نعم",OP_Target,E5))+IF(W5=1,SUMIFS(OP_Area,OP_Space,B5,OP_Wall,D5,OP_DedFin,"نعم",OP_Target,""),0))) | O5: =IF(OR(U5="",K5=""),"",N(M5)+N(N5)) | P5: =IF(OR(U5="",K5=""),"",K5-O5) | Q5: =IF(E5="","",IFERROR(IF(INDEX(WallUnit,MATCH(E5,WallMat,0))="","م²",INDEX(WallUnit,MATCH(E5,WallMat,0))),"م²")) | T5: =IF(U5="","",IF(V5=1,"تكرار — غير محتسب",IF(B5="","ناقص بيانات: كود الفراغ",IF(COUNTIF(SpaceCodes,B5)=0,"ناقص بيانات: الفراغ غير مسجل",IF(D5="","ناقص بيانات: كود الحائط",IF(E5="","ناقص بيانات: الخامة",IF(AND(K5="",I5="يدوي"),"ناقص قياس: أدخل المساحة المباشرة",IF(AND(K5="",J5<>""),"ناقص قياس: اختر «يدوي» أو أدخل الطول والارتفاع",IF(K5="","ناقص قياس",IF(O5>K5+0.000001,"خطأ خصم: الخصم أكبر من الإجمالي",IF(R5="نعم","يحتاج مراجعة","مكتمل"))))))))))) | U5: =IF(COUNTA(B5,D5:J5,N5)=0,"",B5&"|"&D5&"|"&E5) | V5: =IF(OR(U5="",D5=""),0,IF(SUMPRODUCT(--(U$4:U5=U5))>1,1,0)) -> 0 | W5: =IF(OR(U5="",B5="",D5=""),0,COUNTIFS(WL_Space,B5,WL_Wall,D5,WL_Dup,0)) -> 0 | X5: =IF(OR(U5="",V5=1,L5="لا"),0,1) -> 0
A6: 3 | C6: =IF(B6="","",IFERROR(INDEX(SpaceNames,MATCH(B6,SpaceCodes,0))&"","")) | K6: =IF(U6="","",IF(V6=1,0,IF(I6="يدوي",IF(J6<>"",J6*IF(H6="",1,H6),""),IF(AND(F6<>"",G6<>""),F6*G6*IF(H6="",1,H6),"")))) | M6: =IF(U6="","",IF(OR(X6=0,B6="",D6=""),0,IF(E6="",0,SUMIFS(OP_Area,OP_Space,B6,OP_Wall,D6,OP_DedFin,"نعم",OP_Target,E6))+IF(W6=1,SUMIFS(OP_Area,OP_Space,B6,OP_Wall,D6,OP_DedFin,"نعم",OP_Target,""),0))) | O6: =IF(OR(U6="",K6=""),"",N(M6)+N(N6)) | P6: =IF(OR(U6="",K6=""),"",K6-O6) | Q6: =IF(E6="","",IFERROR(IF(INDEX(WallUnit,MATCH(E6,WallMat,0))="","م²",INDEX(WallUnit,MATCH(E6,WallMat,0))),"م²")) | T6: =IF(U6="","",IF(V6=1,"تكرار — غير محتسب",IF(B6="","ناقص بيانات: كود الفراغ",IF(COUNTIF(SpaceCodes,B6)=0,"ناقص بيانات: الفراغ غير مسجل",IF(D6="","ناقص بيانات: كود الحائط",IF(E6="","ناقص بيانات: الخامة",IF(AND(K6="",I6="يدوي"),"ناقص قياس: أدخل المساحة المباشرة",IF(AND(K6="",J6<>""),"ناقص قياس: اختر «يدوي» أو أدخل الطول والارتفاع",IF(K6="","ناقص قياس",IF(O6>K6+0.000001,"خطأ خصم: الخصم أكبر من الإجمالي",IF(R6="نعم","يحتاج مراجعة","مكتمل"))))))))))) | U6: =IF(COUNTA(B6,D6:J6,N6)=0,"",B6&"|"&D6&"|"&E6) | V6: =IF(OR(U6="",D6=""),0,IF(SUMPRODUCT(--(U$4:U6=U6))>1,1,0)) -> 0 | W6: =IF(OR(U6="",B6="",D6=""),0,COUNTIFS(WL_Space,B6,WL_Wall,D6,WL_Dup,0)) -> 0 | X6: =IF(OR(U6="",V6=1,L6="لا"),0,1) -> 0
A7: 4 | C7: =IF(B7="","",IFERROR(INDEX(SpaceNames,MATCH(B7,SpaceCodes,0))&"","")) | K7: =IF(U7="","",IF(V7=1,0,IF(I7="يدوي",IF(J7<>"",J7*IF(H7="",1,H7),""),IF(AND(F7<>"",G7<>""),F7*G7*IF(H7="",1,H7),"")))) | M7: =IF(U7="","",IF(OR(X7=0,B7="",D7=""),0,IF(E7="",0,SUMIFS(OP_Area,OP_Space,B7,OP_Wall,D7,OP_DedFin,"نعم",OP_Target,E7))+IF(W7=1,SUMIFS(OP_Area,OP_Space,B7,OP_Wall,D7,OP_DedFin,"نعم",OP_Target,""),0))) | O7: =IF(OR(U7="",K7=""),"",N(M7)+N(N7)) | P7: =IF(OR(U7="",K7=""),"",K7-O7) | Q7: =IF(E7="","",IFERROR(IF(INDEX(WallUnit,MATCH(E7,WallMat,0))="","م²",INDEX(WallUnit,MATCH(E7,WallMat,0))),"م²")) | T7: =IF(U7="","",IF(V7=1,"تكرار — غير محتسب",IF(B7="","ناقص بيانات: كود الفراغ",IF(COUNTIF(SpaceCodes,B7)=0,"ناقص بيانات: الفراغ غير مسجل",IF(D7="","ناقص بيانات: كود الحائط",IF(E7="","ناقص بيانات: الخامة",IF(AND(K7="",I7="يدوي"),"ناقص قياس: أدخل المساحة المباشرة",IF(AND(K7="",J7<>""),"ناقص قياس: اختر «يدوي» أو أدخل الطول والارتفاع",IF(K7="","ناقص قياس",IF(O7>K7+0.000001,"خطأ خصم: الخصم أكبر من الإجمالي",IF(R7="نعم","يحتاج مراجعة","مكتمل"))))))))))) | U7: =IF(COUNTA(B7,D7:J7,N7)=0,"",B7&"|"&D7&"|"&E7) | V7: =IF(OR(U7="",D7=""),0,IF(SUMPRODUCT(--(U$4:U7=U7))>1,1,0)) -> 0 | W7: =IF(OR(U7="",B7="",D7=""),0,COUNTIFS(WL_Space,B7,WL_Wall,D7,WL_Dup,0)) -> 0 | X7: =IF(OR(U7="",V7=1,L7="لا"),0,1) -> 0
A8: 5 | C8: =IF(B8="","",IFERROR(INDEX(SpaceNames,MATCH(B8,SpaceCodes,0))&"","")) | K8: =IF(U8="","",IF(V8=1,0,IF(I8="يدوي",IF(J8<>"",J8*IF(H8="",1,H8),""),IF(AND(F8<>"",G8<>""),F8*G8*IF(H8="",1,H8),"")))) | M8: =IF(U8="","",IF(OR(X8=0,B8="",D8=""),0,IF(E8="",0,SUMIFS(OP_Area,OP_Space,B8,OP_Wall,D8,OP_DedFin,"نعم",OP_Target,E8))+IF(W8=1,SUMIFS(OP_Area,OP_Space,B8,OP_Wall,D8,OP_DedFin,"نعم",OP_Target,""),0))) | O8: =IF(OR(U8="",K8=""),"",N(M8)+N(N8)) | P8: =IF(OR(U8="",K8=""),"",K8-O8) | Q8: =IF(E8="","",IFERROR(IF(INDEX(WallUnit,MATCH(E8,WallMat,0))="","م²",INDEX(WallUnit,MATCH(E8,WallMat,0))),"م²")) | T8: =IF(U8="","",IF(V8=1,"تكرار — غير محتسب",IF(B8="","ناقص بيانات: كود الفراغ",IF(COUNTIF(SpaceCodes,B8)=0,"ناقص بيانات: الفراغ غير مسجل",IF(D8="","ناقص بيانات: كود الحائط",IF(E8="","ناقص بيانات: الخامة",IF(AND(K8="",I8="يدوي"),"ناقص قياس: أدخل المساحة المباشرة",IF(AND(K8="",J8<>""),"ناقص قياس: اختر «يدوي» أو أدخل الطول والارتفاع",IF(K8="","ناقص قياس",IF(O8>K8+0.000001,"خطأ خصم: الخصم أكبر من الإجمالي",IF(R8="نعم","يحتاج مراجعة","مكتمل"))))))))))) | U8: =IF(COUNTA(B8,D8:J8,N8)=0,"",B8&"|"&D8&"|"&E8) | V8: =IF(OR(U8="",D8=""),0,IF(SUMPRODUCT(--(U$4:U8=U8))>1,1,0)) -> 0 | W8: =IF(OR(U8="",B8="",D8=""),0,COUNTIFS(WL_Space,B8,WL_Wall,D8,WL_Dup,0)) -> 0 | X8: =IF(OR(U8="",V8=1,L8="لا"),0,1) -> 0
A9: 6 | C9: =IF(B9="","",IFERROR(INDEX(SpaceNames,MATCH(B9,SpaceCodes,0))&"","")) | K9: =IF(U9="","",IF(V9=1,0,IF(I9="يدوي",IF(J9<>"",J9*IF(H9="",1,H9),""),IF(AND(F9<>"",G9<>""),F9*G9*IF(H9="",1,H9),"")))) | M9: =IF(U9="","",IF(OR(X9=0,B9="",D9=""),0,IF(E9="",0,SUMIFS(OP_Area,OP_Space,B9,OP_Wall,D9,OP_DedFin,"نعم",OP_Target,E9))+IF(W9=1,SUMIFS(OP_Area,OP_Space,B9,OP_Wall,D9,OP_DedFin,"نعم",OP_Target,""),0))) | O9: =IF(OR(U9="",K9=""),"",N(M9)+N(N9)) | P9: =IF(OR(U9="",K9=""),"",K9-O9) | Q9: =IF(E9="","",IFERROR(IF(INDEX(WallUnit,MATCH(E9,WallMat,0))="","م²",INDEX(WallUnit,MATCH(E9,WallMat,0))),"م²")) | T9: =IF(U9="","",IF(V9=1,"تكرار — غير محتسب",IF(B9="","ناقص بيانات: كود الفراغ",IF(COUNTIF(SpaceCodes,B9)=0,"ناقص بيانات: الفراغ غير مسجل",IF(D9="","ناقص بيانات: كود الحائط",IF(E9="","ناقص بيانات: الخامة",IF(AND(K9="",I9="يدوي"),"ناقص قياس: أدخل المساحة المباشرة",IF(AND(K9="",J9<>""),"ناقص قياس: اختر «يدوي» أو أدخل الطول والارتفاع",IF(K9="","ناقص قياس",IF(O9>K9+0.000001,"خطأ خصم: الخصم أكبر من الإجمالي",IF(R9="نعم","يحتاج مراجعة","مكتمل"))))))))))) | U9: =IF(COUNTA(B9,D9:J9,N9)=0,"",B9&"|"&D9&"|"&E9) | V9: =IF(OR(U9="",D9=""),0,IF(SUMPRODUCT(--(U$4:U9=U9))>1,1,0)) -> 0 | W9: =IF(OR(U9="",B9="",D9=""),0,COUNTIFS(WL_Space,B9,WL_Wall,D9,WL_Dup,0)) -> 0 | X9: =IF(OR(U9="",V9=1,L9="لا"),0,1) -> 0
A10: 7 | C10: =IF(B10="","",IFERROR(INDEX(SpaceNames,MATCH(B10,SpaceCodes,0))&"","")) | K10: =IF(U10="","",IF(V10=1,0,IF(I10="يدوي",IF(J10<>"",J10*IF(H10="",1,H10),""),IF(AND(F10<>"",G10<>""),F10*G10*IF(H10="",1,H10),"")))) | M10: =IF(U10="","",IF(OR(X10=0,B10="",D10=""),0,IF(E10="",0,SUMIFS(OP_Area,OP_Space,B10,OP_Wall,D10,OP_DedFin,"نعم",OP_Target,E10))+IF(W10=1,SUMIFS(OP_Area,OP_Space,B10,OP_Wall,D10,OP_DedFin,"نعم",OP_Target,""),0))) | O10: =IF(OR(U10="",K10=""),"",N(M10)+N(N10)) | P10: =IF(OR(U10="",K10=""),"",K10-O10) | Q10: =IF(E10="","",IFERROR(IF(INDEX(WallUnit,MATCH(E10,WallMat,0))="","م²",INDEX(WallUnit,MATCH(E10,WallMat,0))),"م²")) | T10: =IF(U10="","",IF(V10=1,"تكرار — غير محتسب",IF(B10="","ناقص بيانات: كود الفراغ",IF(COUNTIF(SpaceCodes,B10)=0,"ناقص بيانات: الفراغ غير مسجل",IF(D10="","ناقص بيانات: كود الحائط",IF(E10="","ناقص بيانات: الخامة",IF(AND(K10="",I10="يدوي"),"ناقص قياس: أدخل المساحة المباشرة",IF(AND(K10="",J10<>""),"ناقص قياس: اختر «يدوي» أو أدخل الطول والارتفاع",IF(K10="","ناقص قياس",IF(O10>K10+0.000001,"خطأ خصم: الخصم أكبر من الإجمالي",IF(R10="نعم","يحتاج مراجعة","مكتمل"))))))))))) | U10: =IF(COUNTA(B10,D10:J10,N10)=0,"",B10&"|"&D10&"|"&E10) | V10: =IF(OR(U10="",D10=""),0,IF(SUMPRODUCT(--(U$4:U10=U10))>1,1,0)) -> 0 | W10: =IF(OR(U10="",B10="",D10=""),0,COUNTIFS(WL_Space,B10,WL_Wall,D10,WL_Dup,0)) -> 0 | X10: =IF(OR(U10="",V10=1,L10="لا"),0,1) -> 0
A11: 8 | C11: =IF(B11="","",IFERROR(INDEX(SpaceNames,MATCH(B11,SpaceCodes,0))&"","")) | K11: =IF(U11="","",IF(V11=1,0,IF(I11="يدوي",IF(J11<>"",J11*IF(H11="",1,H11),""),IF(AND(F11<>"",G11<>""),F11*G11*IF(H11="",1,H11),"")))) | M11: =IF(U11="","",IF(OR(X11=0,B11="",D11=""),0,IF(E11="",0,SUMIFS(OP_Area,OP_Space,B11,OP_Wall,D11,OP_DedFin,"نعم",OP_Target,E11))+IF(W11=1,SUMIFS(OP_Area,OP_Space,B11,OP_Wall,D11,OP_DedFin,"نعم",OP_Target,""),0))) | O11: =IF(OR(U11="",K11=""),"",N(M11)+N(N11)) | P11: =IF(OR(U11="",K11=""),"",K11-O11) | Q11: =IF(E11="","",IFERROR(IF(INDEX(WallUnit,MATCH(E11,WallMat,0))="","م²",INDEX(WallUnit,MATCH(E11,WallMat,0))),"م²")) | T11: =IF(U11="","",IF(V11=1,"تكرار — غير محتسب",IF(B11="","ناقص بيانات: كود الفراغ",IF(COUNTIF(SpaceCodes,B11)=0,"ناقص بيانات: الفراغ غير مسجل",IF(D11="","ناقص بيانات: كود الحائط",IF(E11="","ناقص بيانات: الخامة",IF(AND(K11="",I11="يدوي"),"ناقص قياس: أدخل المساحة المباشرة",IF(AND(K11="",J11<>""),"ناقص قياس: اختر «يدوي» أو أدخل الطول والارتفاع",IF(K11="","ناقص قياس",IF(O11>K11+0.000001,"خطأ خصم: الخصم أكبر من الإجمالي",IF(R11="نعم","يحتاج مراجعة","مكتمل"))))))))))) | U11: =IF(COUNTA(B11,D11:J11,N11)=0,"",B11&"|"&D11&"|"&E11) | V11: =IF(OR(U11="",D11=""),0,IF(SUMPRODUCT(--(U$4:U11=U11))>1,1,0)) -> 0 | W11: =IF(OR(U11="",B11="",D11=""),0,COUNTIFS(WL_Space,B11,WL_Wall,D11,WL_Dup,0)) -> 0 | X11: =IF(OR(U11="",V11=1,L11="لا"),0,1) -> 0
A12: 9 | C12: =IF(B12="","",IFERROR(INDEX(SpaceNames,MATCH(B12,SpaceCodes,0))&"","")) | K12: =IF(U12="","",IF(V12=1,0,IF(I12="يدوي",IF(J12<>"",J12*IF(H12="",1,H12),""),IF(AND(F12<>"",G12<>""),F12*G12*IF(H12="",1,H12),"")))) | M12: =IF(U12="","",IF(OR(X12=0,B12="",D12=""),0,IF(E12="",0,SUMIFS(OP_Area,OP_Space,B12,OP_Wall,D12,OP_DedFin,"نعم",OP_Target,E12))+IF(W12=1,SUMIFS(OP_Area,OP_Space,B12,OP_Wall,D12,OP_DedFin,"نعم",OP_Target,""),0))) | O12: =IF(OR(U12="",K12=""),"",N(M12)+N(N12)) | P12: =IF(OR(U12="",K12=""),"",K12-O12) | Q12: =IF(E12="","",IFERROR(IF(INDEX(WallUnit,MATCH(E12,WallMat,0))="","م²",INDEX(WallUnit,MATCH(E12,WallMat,0))),"م²")) | T12: =IF(U12="","",IF(V12=1,"تكرار — غير محتسب",IF(B12="","ناقص بيانات: كود الفراغ",IF(COUNTIF(SpaceCodes,B12)=0,"ناقص بيانات: الفراغ غير مسجل",IF(D12="","ناقص بيانات: كود الحائط",IF(E12="","ناقص بيانات: الخامة",IF(AND(K12="",I12="يدوي"),"ناقص قياس: أدخل المساحة المباشرة",IF(AND(K12="",J12<>""),"ناقص قياس: اختر «يدوي» أو أدخل الطول والارتفاع",IF(K12="","ناقص قياس",IF(O12>K12+0.000001,"خطأ خصم: الخصم أكبر من الإجمالي",IF(R12="نعم","يحتاج مراجعة","مكتمل"))))))))))) | U12: =IF(COUNTA(B12,D12:J12,N12)=0,"",B12&"|"&D12&"|"&E12) | V12: =IF(OR(U12="",D12=""),0,IF(SUMPRODUCT(--(U$4:U12=U12))>1,1,0)) -> 0 | W12: =IF(OR(U12="",B12="",D12=""),0,COUNTIFS(WL_Space,B12,WL_Wall,D12,WL_Dup,0)) -> 0 | X12: =IF(OR(U12="",V12=1,L12="لا"),0,1) -> 0
A13: 10 | C13: =IF(B13="","",IFERROR(INDEX(SpaceNames,MATCH(B13,SpaceCodes,0))&"","")) | K13: =IF(U13="","",IF(V13=1,0,IF(I13="يدوي",IF(J13<>"",J13*IF(H13="",1,H13),""),IF(AND(F13<>"",G13<>""),F13*G13*IF(H13="",1,H13),"")))) | M13: =IF(U13="","",IF(OR(X13=0,B13="",D13=""),0,IF(E13="",0,SUMIFS(OP_Area,OP_Space,B13,OP_Wall,D13,OP_DedFin,"نعم",OP_Target,E13))+IF(W13=1,SUMIFS(OP_Area,OP_Space,B13,OP_Wall,D13,OP_DedFin,"نعم",OP_Target,""),0))) | O13: =IF(OR(U13="",K13=""),"",N(M13)+N(N13)) | P13: =IF(OR(U13="",K13=""),"",K13-O13) | Q13: =IF(E13="","",IFERROR(IF(INDEX(WallUnit,MATCH(E13,WallMat,0))="","م²",INDEX(WallUnit,MATCH(E13,WallMat,0))),"م²")) | T13: =IF(U13="","",IF(V13=1,"تكرار — غير محتسب",IF(B13="","ناقص بيانات: كود الفراغ",IF(COUNTIF(SpaceCodes,B13)=0,"ناقص بيانات: الفراغ غير مسجل",IF(D13="","ناقص بيانات: كود الحائط",IF(E13="","ناقص بيانات: الخامة",IF(AND(K13="",I13="يدوي"),"ناقص قياس: أدخل المساحة المباشرة",IF(AND(K13="",J13<>""),"ناقص قياس: اختر «يدوي» أو أدخل الطول والارتفاع",IF(K13="","ناقص قياس",IF(O13>K13+0.000001,"خطأ خصم: الخصم أكبر من الإجمالي",IF(R13="نعم","يحتاج مراجعة","مكتمل"))))))))))) | U13: =IF(COUNTA(B13,D13:J13,N13)=0,"",B13&"|"&D13&"|"&E13) | V13: =IF(OR(U13="",D13=""),0,IF(SUMPRODUCT(--(U$4:U13=U13))>1,1,0)) -> 0 | W13: =IF(OR(U13="",B13="",D13=""),0,COUNTIFS(WL_Space,B13,WL_Wall,D13,WL_Dup,0)) -> 0 | X13: =IF(OR(U13="",V13=1,L13="لا"),0,1) -> 0
A14: 11 | C14: =IF(B14="","",IFERROR(INDEX(SpaceNames,MATCH(B14,SpaceCodes,0))&"","")) | K14: =IF(U14="","",IF(V14=1,0,IF(I14="يدوي",IF(J14<>"",J14*IF(H14="",1,H14),""),IF(AND(F14<>"",G14<>""),F14*G14*IF(H14="",1,H14),"")))) | M14: =IF(U14="","",IF(OR(X14=0,B14="",D14=""),0,IF(E14="",0,SUMIFS(OP_Area,OP_Space,B14,OP_Wall,D14,OP_DedFin,"نعم",OP_Target,E14))+IF(W14=1,SUMIFS(OP_Area,OP_Space,B14,OP_Wall,D14,OP_DedFin,"نعم",OP_Target,""),0))) | O14: =IF(OR(U14="",K14=""),"",N(M14)+N(N14)) | P14: =IF(OR(U14="",K14=""),"",K14-O14) | Q14: =IF(E14="","",IFERROR(IF(INDEX(WallUnit,MATCH(E14,WallMat,0))="","م²",INDEX(WallUnit,MATCH(E14,WallMat,0))),"م²")) | T14: =IF(U14="","",IF(V14=1,"تكرار — غير محتسب",IF(B14="","ناقص بيانات: كود الفراغ",IF(COUNTIF(SpaceCodes,B14)=0,"ناقص بيانات: الفراغ غير مسجل",IF(D14="","ناقص بيانات: كود الحائط",IF(E14="","ناقص بيانات: الخامة",IF(AND(K14="",I14="يدوي"),"ناقص قياس: أدخل المساحة المباشرة",IF(AND(K14="",J14<>""),"ناقص قياس: اختر «يدوي» أو أدخل الطول والارتفاع",IF(K14="","ناقص قياس",IF(O14>K14+0.000001,"خطأ خصم: الخصم أكبر من الإجمالي",IF(R14="نعم","يحتاج مراجعة","مكتمل"))))))))))) | U14: =IF(COUNTA(B14,D14:J14,N14)=0,"",B14&"|"&D14&"|"&E14) | V14: =IF(OR(U14="",D14=""),0,IF(SUMPRODUCT(--(U$4:U14=U14))>1,1,0)) -> 0 | W14: =IF(OR(U14="",B14="",D14=""),0,COUNTIFS(WL_Space,B14,WL_Wall,D14,WL_Dup,0)) -> 0 | X14: =IF(OR(U14="",V14=1,L14="لا"),0,1) -> 0
A15: 12 | C15: =IF(B15="","",IFERROR(INDEX(SpaceNames,MATCH(B15,SpaceCodes,0))&"","")) | K15: =IF(U15="","",IF(V15=1,0,IF(I15="يدوي",IF(J15<>"",J15*IF(H15="",1,H15),""),IF(AND(F15<>"",G15<>""),F15*G15*IF(H15="",1,H15),"")))) | M15: =IF(U15="","",IF(OR(X15=0,B15="",D15=""),0,IF(E15="",0,SUMIFS(OP_Area,OP_Space,B15,OP_Wall,D15,OP_DedFin,"نعم",OP_Target,E15))+IF(W15=1,SUMIFS(OP_Area,OP_Space,B15,OP_Wall,D15,OP_DedFin,"نعم",OP_Target,""),0))) | O15: =IF(OR(U15="",K15=""),"",N(M15)+N(N15)) | P15: =IF(OR(U15="",K15=""),"",K15-O15) | Q15: =IF(E15="","",IFERROR(IF(INDEX(WallUnit,MATCH(E15,WallMat,0))="","م²",INDEX(WallUnit,MATCH(E15,WallMat,0))),"م²")) | T15: =IF(U15="","",IF(V15=1,"تكرار — غير محتسب",IF(B15="","ناقص بيانات: كود الفراغ",IF(COUNTIF(SpaceCodes,B15)=0,"ناقص بيانات: الفراغ غير مسجل",IF(D15="","ناقص بيانات: كود الحائط",IF(E15="","ناقص بيانات: الخامة",IF(AND(K15="",I15="يدوي"),"ناقص قياس: أدخل المساحة المباشرة",IF(AND(K15="",J15<>""),"ناقص قياس: اختر «يدوي» أو أدخل الطول والارتفاع",IF(K15="","ناقص قياس",IF(O15>K15+0.000001,"خطأ خصم: الخصم أكبر من الإجمالي",IF(R15="نعم","يحتاج مراجعة","مكتمل"))))))))))) | U15: =IF(COUNTA(B15,D15:J15,N15)=0,"",B15&"|"&D15&"|"&E15) | V15: =IF(OR(U15="",D15=""),0,IF(SUMPRODUCT(--(U$4:U15=U15))>1,1,0)) -> 0 | W15: =IF(OR(U15="",B15="",D15=""),0,COUNTIFS(WL_Space,B15,WL_Wall,D15,WL_Dup,0)) -> 0 | X15: =IF(OR(U15="",V15=1,L15="لا"),0,1) -> 0
... A403: 400 | C403: =IF(B403="","",IFERROR(INDEX(SpaceNames,MATCH(B403,SpaceCodes,0))&"","")) | K403: =IF(U403="","",IF(V403=1,0,IF(I403="يدوي",IF(J403<>"",J403*IF(H403="",1,H403),""),IF(AND(F403<>"",G403<>""),F403*G403*IF(H403="",1,H403),"")))) | M403: =IF(U403="","",IF(OR(X403=0,B403="",D403=""),0,IF(E403="",0,SUMIFS(OP_Area,OP_Space,B403,OP_Wall,D403,OP_DedFin,"نعم",OP_Target,E403))+IF(W403=1,SUMIFS(OP_Area,OP_Space,B403,OP_Wall,D403,OP_DedFin,"نعم",OP_Target,""),0))) | O403: =IF(OR(U403="",K403=""),"",N(M403)+N(N403)) | P403: =IF(OR(U403="",K403=""),"",K403-O403) | Q403: =IF(E403="","",IFERROR(IF(INDEX(WallUnit,MATCH(E403,WallMat,0))="","م²",INDEX(WallUnit,MATCH(E403,WallMat,0))),"م²")) | T403: =IF(U403="","",IF(V403=1,"تكرار — غير محتسب",IF(B403="","ناقص بيانات: كود الفراغ",IF(COUNTIF(SpaceCodes,B403)=0,"ناقص بيانات: الفراغ غير مسجل",IF(D403="","ناقص بيانات: كود الحائط",IF(E403="","ناقص بيانات: الخامة",IF(AND(K403="",I403="يدوي"),"ناقص قياس: أدخل المساحة المباشرة",IF(AND(K403="",J403<>""),"ناقص قياس: اختر «يدوي» أو أدخل الطول والارتفاع",IF(K403="","ناقص قياس",IF(O403>K403+0.000001,"خطأ خصم: الخصم أكبر من الإجمالي",IF(R403="نعم","يحتاج مراجعة","مكتمل"))))))))))) | U403: =IF(COUNTA(B403,D403:J403,N403)=0,"",B403&"|"&D403&"|"&E403) | V403: =IF(OR(U403="",D403=""),0,IF(SUMPRODUCT(--(U$4:U403=U403))>1,1,0)) -> 0 | W403: =IF(OR(U403="",B403="",D403=""),0,COUNTIFS(WL_Space,B403,WL_Wall,D403,WL_Dup,0)) -> 0 | X403: =IF(OR(U403="",V403=1,L403="لا"),0,1) -> 0

Sheet حصر الفتحات والخصومات
A1: حصر الفتحات والخصومات — صف لكل فتحة، وتُخصم من الحائط المحدد لها فقط
A2: إجمالي الصفوف الظاهرة بعد الفلتر ← | J2: =SUBTOTAL(109,J$4:J$303) -> 0 | O2: =SUBTOTAL(109,O$4:O$303) -> 0 | P2: =SUBTOTAL(109,P$4:P$303) -> 0 | Q2: =SUBTOTAL(109,Q$4:Q$303) -> 0 | T2: ="غير مكتمل: "&(COUNTIF(T$4:T$303,"?*")-COUNTIF(T$4:T$303,"مكتمل")) -> غير مكتمل: 0
A3: م | B3: كود الفتحة (فريد) | C3: كود الفراغ | D3: اسم الفراغ | E3: كود الحائط الواقعة عليه | F3: نوع الفتحة | G3: العرض (م) | H3: الارتفاع (م) | I3: العدد (فارغ = 1) | J3: مساحة الفتحة (م²) | K3: خصم من تشطيب الحوائط؟ | L3: الخامة المخصوم منها (عند تعدد خامات الحائط) | M3: خصم من اللياسة؟ | N3: خصم من الوزرات؟ | O3: مخصوم فعليًا من التشطيب (م²) | P3: مخصوم فعليًا من اللياسة (م²) | Q3: مخصوم فعليًا من الوزرات (م.ط) | R3: يحتاج مراجعة؟ | S3: ملاحظات | T3: الحالة | U3: عرض إجمالي | V3: تكرار | W3: بدأ
A4: 1 | D4: =IF(C4="","",IFERROR(INDEX(SpaceNames,MATCH(C4,SpaceCodes,0))&"","")) | J4: =IF(W4=0,"",IF(V4=1,0,IF(AND(G4<>"",H4<>""),G4*H4*IF(I4="",1,I4),""))) | O4: =IF(OR(W4=0,J4=""),"",IF(OR(K4<>"نعم",C4="",E4=""),0,IF(L4<>"",IF(COUNTIFS(WL_Space,C4,WL_Wall,E4,WL_Mat,L4,WL_DedOn,1)>0,J4,0),IF(AND(COUNTIFS(WL_Space,C4,WL_Wall,E4,WL_Dup,0)=1,COUNTIFS(WL_Space,C4,WL_Wall,E4,WL_DedOn,1)=1),J4,0)))) | P4: =IF(OR(W4=0,J4=""),"",IF(OR(M4<>"نعم",C4="",E4=""),0,J4*SUMIFS(PL_FacesEff,PL_Space,C4,PL_Wall,E4))) | Q4: =IF(W4=0,"",IF(OR(N4<>"نعم",C4=""),0,IF(COUNTIFS(LN_Space,C4,LN_AutoEff,1)>0,U4,0))) | T4: =IF(W4=0,"",IF(B4="","ناقص بيانات: كود الفتحة",IF(V4=1,"تكرار كود الفتحة — غير محتسب",IF(C4="","ناقص بيانات: كود الفراغ",IF(COUNTIF(SpaceCodes,C4)=0,"ناقص بيانات: الفراغ غير مسجل",IF(E4="","ناقص بيانات: كود الحائط",IF(J4="","ناقص قياس",IF(AND(K4="",M4="",N4=""),"ناقص بيانات: حدد خيارات الخصم (نعم/لا)",IF(AND(K4="نعم",N(O4)=0,L4="",COUNTIFS(WL_Space,C4,WL_Wall,E4,WL_Dup,0)>1),"تنبيه خصم: للحائط أكثر من خامة — حدد الخامة المخصوم منها",IF(AND(K4="نعم",N(O4)=0,IF(L4="",COUNTIFS(WL_Space,C4,WL_Wall,E4,WL_Dup,0),COUNTIFS(WL_Space,C4,WL_Wall,E4,WL_Mat,L4,WL_Dup,0))>0),"تنبيه خصم: خصم الفتحات موقوف («لا») في سجل الحائط",IF(AND(K4="نعم",N(O4)=0),"تنبيه خصم: الحائط/الخامة غير مسجلة في حصر الحوائط",IF(AND(M4="نعم",N(P4)=0),"تنبيه خصم: الحائط غير مسجل في حصر اللياسة",IF(AND(N4="نعم",N(Q4)=0),"تنبيه خصم: لا يوجد سجل وزرات بخصم تلقائي للفراغ",IF(R4="نعم","يحتاج مراجعة","مكتمل")))))))))))))) | U4: =IF(OR(W4=0,V4=1,G4=""),0,G4*IF(I4="",1,I4)) -> 0 | V4: =IF(B4="",0,IF(SUMPRODUCT(--(B$4:B4=B4))>1,1,0)) -> 0 | W4: =IF(COUNTA(B4:C4,E4:I4,K4:N4)=0,0,1) -> 0
A5: 2 | D5: =IF(C5="","",IFERROR(INDEX(SpaceNames,MATCH(C5,SpaceCodes,0))&"","")) | J5: =IF(W5=0,"",IF(V5=1,0,IF(AND(G5<>"",H5<>""),G5*H5*IF(I5="",1,I5),""))) | O5: =IF(OR(W5=0,J5=""),"",IF(OR(K5<>"نعم",C5="",E5=""),0,IF(L5<>"",IF(COUNTIFS(WL_Space,C5,WL_Wall,E5,WL_Mat,L5,WL_DedOn,1)>0,J5,0),IF(AND(COUNTIFS(WL_Space,C5,WL_Wall,E5,WL_Dup,0)=1,COUNTIFS(WL_Space,C5,WL_Wall,E5,WL_DedOn,1)=1),J5,0)))) | P5: =IF(OR(W5=0,J5=""),"",IF(OR(M5<>"نعم",C5="",E5=""),0,J5*SUMIFS(PL_FacesEff,PL_Space,C5,PL_Wall,E5))) | Q5: =IF(W5=0,"",IF(OR(N5<>"نعم",C5=""),0,IF(COUNTIFS(LN_Space,C5,LN_AutoEff,1)>0,U5,0))) | T5: =IF(W5=0,"",IF(B5="","ناقص بيانات: كود الفتحة",IF(V5=1,"تكرار كود الفتحة — غير محتسب",IF(C5="","ناقص بيانات: كود الفراغ",IF(COUNTIF(SpaceCodes,C5)=0,"ناقص بيانات: الفراغ غير مسجل",IF(E5="","ناقص بيانات: كود الحائط",IF(J5="","ناقص قياس",IF(AND(K5="",M5="",N5=""),"ناقص بيانات: حدد خيارات الخصم (نعم/لا)",IF(AND(K5="نعم",N(O5)=0,L5="",COUNTIFS(WL_Space,C5,WL_Wall,E5,WL_Dup,0)>1),"تنبيه خصم: للحائط أكثر من خامة — حدد الخامة المخصوم منها",IF(AND(K5="نعم",N(O5)=0,IF(L5="",COUNTIFS(WL_Space,C5,WL_Wall,E5,WL_Dup,0),COUNTIFS(WL_Space,C5,WL_Wall,E5,WL_Mat,L5,WL_Dup,0))>0),"تنبيه خصم: خصم الفتحات موقوف («لا») في سجل الحائط",IF(AND(K5="نعم",N(O5)=0),"تنبيه خصم: الحائط/الخامة غير مسجلة في حصر الحوائط",IF(AND(M5="نعم",N(P5)=0),"تنبيه خصم: الحائط غير مسجل في حصر اللياسة",IF(AND(N5="نعم",N(Q5)=0),"تنبيه خصم: لا يوجد سجل وزرات بخصم تلقائي للفراغ",IF(R5="نعم","يحتاج مراجعة","مكتمل")))))))))))))) | U5: =IF(OR(W5=0,V5=1,G5=""),0,G5*IF(I5="",1,I5)) -> 0 | V5: =IF(B5="",0,IF(SUMPRODUCT(--(B$4:B5=B5))>1,1,0)) -> 0 | W5: =IF(COUNTA(B5:C5,E5:I5,K5:N5)=0,0,1) -> 0
A6: 3 | D6: =IF(C6="","",IFERROR(INDEX(SpaceNames,MATCH(C6,SpaceCodes,0))&"","")) | J6: =IF(W6=0,"",IF(V6=1,0,IF(AND(G6<>"",H6<>""),G6*H6*IF(I6="",1,I6),""))) | O6: =IF(OR(W6=0,J6=""),"",IF(OR(K6<>"نعم",C6="",E6=""),0,IF(L6<>"",IF(COUNTIFS(WL_Space,C6,WL_Wall,E6,WL_Mat,L6,WL_DedOn,1)>0,J6,0),IF(AND(COUNTIFS(WL_Space,C6,WL_Wall,E6,WL_Dup,0)=1,COUNTIFS(WL_Space,C6,WL_Wall,E6,WL_DedOn,1)=1),J6,0)))) | P6: =IF(OR(W6=0,J6=""),"",IF(OR(M6<>"نعم",C6="",E6=""),0,J6*SUMIFS(PL_FacesEff,PL_Space,C6,PL_Wall,E6))) | Q6: =IF(W6=0,"",IF(OR(N6<>"نعم",C6=""),0,IF(COUNTIFS(LN_Space,C6,LN_AutoEff,1)>0,U6,0))) | T6: =IF(W6=0,"",IF(B6="","ناقص بيانات: كود الفتحة",IF(V6=1,"تكرار كود الفتحة — غير محتسب",IF(C6="","ناقص بيانات: كود الفراغ",IF(COUNTIF(SpaceCodes,C6)=0,"ناقص بيانات: الفراغ غير مسجل",IF(E6="","ناقص بيانات: كود الحائط",IF(J6="","ناقص قياس",IF(AND(K6="",M6="",N6=""),"ناقص بيانات: حدد خيارات الخصم (نعم/لا)",IF(AND(K6="نعم",N(O6)=0,L6="",COUNTIFS(WL_Space,C6,WL_Wall,E6,WL_Dup,0)>1),"تنبيه خصم: للحائط أكثر من خامة — حدد الخامة المخصوم منها",IF(AND(K6="نعم",N(O6)=0,IF(L6="",COUNTIFS(WL_Space,C6,WL_Wall,E6,WL_Dup,0),COUNTIFS(WL_Space,C6,WL_Wall,E6,WL_Mat,L6,WL_Dup,0))>0),"تنبيه خصم: خصم الفتحات موقوف («لا») في سجل الحائط",IF(AND(K6="نعم",N(O6)=0),"تنبيه خصم: الحائط/الخامة غير مسجلة في حصر الحوائط",IF(AND(M6="نعم",N(P6)=0),"تنبيه خصم: الحائط غير مسجل في حصر اللياسة",IF(AND(N6="نعم",N(Q6)=0),"تنبيه خصم: لا يوجد سجل وزرات بخصم تلقائي للفراغ",IF(R6="نعم","يحتاج مراجعة","مكتمل")))))))))))))) | U6: =IF(OR(W6=0,V6=1,G6=""),0,G6*IF(I6="",1,I6)) -> 0 | V6: =IF(B6="",0,IF(SUMPRODUCT(--(B$4:B6=B6))>1,1,0)) -> 0 | W6: =IF(COUNTA(B6:C6,E6:I6,K6:N6)=0,0,1) -> 0
A7: 4 | D7: =IF(C7="","",IFERROR(INDEX(SpaceNames,MATCH(C7,SpaceCodes,0))&"","")) | J7: =IF(W7=0,"",IF(V7=1,0,IF(AND(G7<>"",H7<>""),G7*H7*IF(I7="",1,I7),""))) | O7: =IF(OR(W7=0,J7=""),"",IF(OR(K7<>"نعم",C7="",E7=""),0,IF(L7<>"",IF(COUNTIFS(WL_Space,C7,WL_Wall,E7,WL_Mat,L7,WL_DedOn,1)>0,J7,0),IF(AND(COUNTIFS(WL_Space,C7,WL_Wall,E7,WL_Dup,0)=1,COUNTIFS(WL_Space,C7,WL_Wall,E7,WL_DedOn,1)=1),J7,0)))) | P7: =IF(OR(W7=0,J7=""),"",IF(OR(M7<>"نعم",C7="",E7=""),0,J7*SUMIFS(PL_FacesEff,PL_Space,C7,PL_Wall,E7))) | Q7: =IF(W7=0,"",IF(OR(N7<>"نعم",C7=""),0,IF(COUNTIFS(LN_Space,C7,LN_AutoEff,1)>0,U7,0))) | T7: =IF(W7=0,"",IF(B7="","ناقص بيانات: كود الفتحة",IF(V7=1,"تكرار كود الفتحة — غير محتسب",IF(C7="","ناقص بيانات: كود الفراغ",IF(COUNTIF(SpaceCodes,C7)=0,"ناقص بيانات: الفراغ غير مسجل",IF(E7="","ناقص بيانات: كود الحائط",IF(J7="","ناقص قياس",IF(AND(K7="",M7="",N7=""),"ناقص بيانات: حدد خيارات الخصم (نعم/لا)",IF(AND(K7="نعم",N(O7)=0,L7="",COUNTIFS(WL_Space,C7,WL_Wall,E7,WL_Dup,0)>1),"تنبيه خصم: للحائط أكثر من خامة — حدد الخامة المخصوم منها",IF(AND(K7="نعم",N(O7)=0,IF(L7="",COUNTIFS(WL_Space,C7,WL_Wall,E7,WL_Dup,0),COUNTIFS(WL_Space,C7,WL_Wall,E7,WL_Mat,L7,WL_Dup,0))>0),"تنبيه خصم: خصم الفتحات موقوف («لا») في سجل الحائط",IF(AND(K7="نعم",N(O7)=0),"تنبيه خصم: الحائط/الخامة غير مسجلة في حصر الحوائط",IF(AND(M7="نعم",N(P7)=0),"تنبيه خصم: الحائط غير مسجل في حصر اللياسة",IF(AND(N7="نعم",N(Q7)=0),"تنبيه خصم: لا يوجد سجل وزرات بخصم تلقائي للفراغ",IF(R7="نعم","يحتاج مراجعة","مكتمل")))))))))))))) | U7: =IF(OR(W7=0,V7=1,G7=""),0,G7*IF(I7="",1,I7)) -> 0 | V7: =IF(B7="",0,IF(SUMPRODUCT(--(B$4:B7=B7))>1,1,0)) -> 0 | W7: =IF(COUNTA(B7:C7,E7:I7,K7:N7)=0,0,1) -> 0
A8: 5 | D8: =IF(C8="","",IFERROR(INDEX(SpaceNames,MATCH(C8,SpaceCodes,0))&"","")) | J8: =IF(W8=0,"",IF(V8=1,0,IF(AND(G8<>"",H8<>""),G8*H8*IF(I8="",1,I8),""))) | O8: =IF(OR(W8=0,J8=""),"",IF(OR(K8<>"نعم",C8="",E8=""),0,IF(L8<>"",IF(COUNTIFS(WL_Space,C8,WL_Wall,E8,WL_Mat,L8,WL_DedOn,1)>0,J8,0),IF(AND(COUNTIFS(WL_Space,C8,WL_Wall,E8,WL_Dup,0)=1,COUNTIFS(WL_Space,C8,WL_Wall,E8,WL_DedOn,1)=1),J8,0)))) | P8: =IF(OR(W8=0,J8=""),"",IF(OR(M8<>"نعم",C8="",E8=""),0,J8*SUMIFS(PL_FacesEff,PL_Space,C8,PL_Wall,E8))) | Q8: =IF(W8=0,"",IF(OR(N8<>"نعم",C8=""),0,IF(COUNTIFS(LN_Space,C8,LN_AutoEff,1)>0,U8,0))) | T8: =IF(W8=0,"",IF(B8="","ناقص بيانات: كود الفتحة",IF(V8=1,"تكرار كود الفتحة — غير محتسب",IF(C8="","ناقص بيانات: كود الفراغ",IF(COUNTIF(SpaceCodes,C8)=0,"ناقص بيانات: الفراغ غير مسجل",IF(E8="","ناقص بيانات: كود الحائط",IF(J8="","ناقص قياس",IF(AND(K8="",M8="",N8=""),"ناقص بيانات: حدد خيارات الخصم (نعم/لا)",IF(AND(K8="نعم",N(O8)=0,L8="",COUNTIFS(WL_Space,C8,WL_Wall,E8,WL_Dup,0)>1),"تنبيه خصم: للحائط أكثر من خامة — حدد الخامة المخصوم منها",IF(AND(K8="نعم",N(O8)=0,IF(L8="",COUNTIFS(WL_Space,C8,WL_Wall,E8,WL_Dup,0),COUNTIFS(WL_Space,C8,WL_Wall,E8,WL_Mat,L8,WL_Dup,0))>0),"تنبيه خصم: خصم الفتحات موقوف («لا») في سجل الحائط",IF(AND(K8="نعم",N(O8)=0),"تنبيه خصم: الحائط/الخامة غير مسجلة في حصر الحوائط",IF(AND(M8="نعم",N(P8)=0),"تنبيه خصم: الحائط غير مسجل في حصر اللياسة",IF(AND(N8="نعم",N(Q8)=0),"تنبيه خصم: لا يوجد سجل وزرات بخصم تلقائي للفراغ",IF(R8="نعم","يحتاج مراجعة","مكتمل")))))))))))))) | U8: =IF(OR(W8=0,V8=1,G8=""),0,G8*IF(I8="",1,I8)) -> 0 | V8: =IF(B8="",0,IF(SUMPRODUCT(--(B$4:B8=B8))>1,1,0)) -> 0 | W8: =IF(COUNTA(B8:C8,E8:I8,K8:N8)=0,0,1) -> 0
A9: 6 | D9: =IF(C9="","",IFERROR(INDEX(SpaceNames,MATCH(C9,SpaceCodes,0))&"","")) | J9: =IF(W9=0,"",IF(V9=1,0,IF(AND(G9<>"",H9<>""),G9*H9*IF(I9="",1,I9),""))) | O9: =IF(OR(W9=0,J9=""),"",IF(OR(K9<>"نعم",C9="",E9=""),0,IF(L9<>"",IF(COUNTIFS(WL_Space,C9,WL_Wall,E9,WL_Mat,L9,WL_DedOn,1)>0,J9,0),IF(AND(COUNTIFS(WL_Space,C9,WL_Wall,E9,WL_Dup,0)=1,COUNTIFS(WL_Space,C9,WL_Wall,E9,WL_DedOn,1)=1),J9,0)))) | P9: =IF(OR(W9=0,J9=""),"",IF(OR(M9<>"نعم",C9="",E9=""),0,J9*SUMIFS(PL_FacesEff,PL_Space,C9,PL_Wall,E9))) | Q9: =IF(W9=0,"",IF(OR(N9<>"نعم",C9=""),0,IF(COUNTIFS(LN_Space,C9,LN_AutoEff,1)>0,U9,0))) | T9: =IF(W9=0,"",IF(B9="","ناقص بيانات: كود الفتحة",IF(V9=1,"تكرار كود الفتحة — غير محتسب",IF(C9="","ناقص بيانات: كود الفراغ",IF(COUNTIF(SpaceCodes,C9)=0,"ناقص بيانات: الفراغ غير مسجل",IF(E9="","ناقص بيانات: كود الحائط",IF(J9="","ناقص قياس",IF(AND(K9="",M9="",N9=""),"ناقص بيانات: حدد خيارات الخصم (نعم/لا)",IF(AND(K9="نعم",N(O9)=0,L9="",COUNTIFS(WL_Space,C9,WL_Wall,E9,WL_Dup,0)>1),"تنبيه خصم: للحائط أكثر من خامة — حدد الخامة المخصوم منها",IF(AND(K9="نعم",N(O9)=0,IF(L9="",COUNTIFS(WL_Space,C9,WL_Wall,E9,WL_Dup,0),COUNTIFS(WL_Space,C9,WL_Wall,E9,WL_Mat,L9,WL_Dup,0))>0),"تنبيه خصم: خصم الفتحات موقوف («لا») في سجل الحائط",IF(AND(K9="نعم",N(O9)=0),"تنبيه خصم: الحائط/الخامة غير مسجلة في حصر الحوائط",IF(AND(M9="نعم",N(P9)=0),"تنبيه خصم: الحائط غير مسجل في حصر اللياسة",IF(AND(N9="نعم",N(Q9)=0),"تنبيه خصم: لا يوجد سجل وزرات بخصم تلقائي للفراغ",IF(R9="نعم","يحتاج مراجعة","مكتمل")))))))))))))) | U9: =IF(OR(W9=0,V9=1,G9=""),0,G9*IF(I9="",1,I9)) -> 0 | V9: =IF(B9="",0,IF(SUMPRODUCT(--(B$4:B9=B9))>1,1,0)) -> 0 | W9: =IF(COUNTA(B9:C9,E9:I9,K9:N9)=0,0,1) -> 0
A10: 7 | D10: =IF(C10="","",IFERROR(INDEX(SpaceNames,MATCH(C10,SpaceCodes,0))&"","")) | J10: =IF(W10=0,"",IF(V10=1,0,IF(AND(G10<>"",H10<>""),G10*H10*IF(I10="",1,I10),""))) | O10: =IF(OR(W10=0,J10=""),"",IF(OR(K10<>"نعم",C10="",E10=""),0,IF(L10<>"",IF(COUNTIFS(WL_Space,C10,WL_Wall,E10,WL_Mat,L10,WL_DedOn,1)>0,J10,0),IF(AND(COUNTIFS(WL_Space,C10,WL_Wall,E10,WL_Dup,0)=1,COUNTIFS(WL_Space,C10,WL_Wall,E10,WL_DedOn,1)=1),J10,0)))) | P10: =IF(OR(W10=0,J10=""),"",IF(OR(M10<>"نعم",C10="",E10=""),0,J10*SUMIFS(PL_FacesEff,PL_Space,C10,PL_Wall,E10))) | Q10: =IF(W10=0,"",IF(OR(N10<>"نعم",C10=""),0,IF(COUNTIFS(LN_Space,C10,LN_AutoEff,1)>0,U10,0))) | T10: =IF(W10=0,"",IF(B10="","ناقص بيانات: كود الفتحة",IF(V10=1,"تكرار كود الفتحة — غير محتسب",IF(C10="","ناقص بيانات: كود الفراغ",IF(COUNTIF(SpaceCodes,C10)=0,"ناقص بيانات: الفراغ غير مسجل",IF(E10="","ناقص بيانات: كود الحائط",IF(J10="","ناقص قياس",IF(AND(K10="",M10="",N10=""),"ناقص بيانات: حدد خيارات الخصم (نعم/لا)",IF(AND(K10="نعم",N(O10)=0,L10="",COUNTIFS(WL_Space,C10,WL_Wall,E10,WL_Dup,0)>1),"تنبيه خصم: للحائط أكثر من خامة — حدد الخامة المخصوم منها",IF(AND(K10="نعم",N(O10)=0,IF(L10="",COUNTIFS(WL_Space,C10,WL_Wall,E10,WL_Dup,0),COUNTIFS(WL_Space,C10,WL_Wall,E10,WL_Mat,L10,WL_Dup,0))>0),"تنبيه خصم: خصم الفتحات موقوف («لا») في سجل الحائط",IF(AND(K10="نعم",N(O10)=0),"تنبيه خصم: الحائط/الخامة غير مسجلة في حصر الحوائط",IF(AND(M10="نعم",N(P10)=0),"تنبيه خصم: الحائط غير مسجل في حصر اللياسة",IF(AND(N10="نعم",N(Q10)=0),"تنبيه خصم: لا يوجد سجل وزرات بخصم تلقائي للفراغ",IF(R10="نعم","يحتاج مراجعة","مكتمل")))))))))))))) | U10: =IF(OR(W10=0,V10=1,G10=""),0,G10*IF(I10="",1,I10)) -> 0 | V10: =IF(B10="",0,IF(SUMPRODUCT(--(B$4:B10=B10))>1,1,0)) -> 0 | W10: =IF(COUNTA(B10:C10,E10:I10,K10:N10)=0,0,1) -> 0
A11: 8 | D11: =IF(C11="","",IFERROR(INDEX(SpaceNames,MATCH(C11,SpaceCodes,0))&"","")) | J11: =IF(W11=0,"",IF(V11=1,0,IF(AND(G11<>"",H11<>""),G11*H11*IF(I11="",1,I11),""))) | O11: =IF(OR(W11=0,J11=""),"",IF(OR(K11<>"نعم",C11="",E11=""),0,IF(L11<>"",IF(COUNTIFS(WL_Space,C11,WL_Wall,E11,WL_Mat,L11,WL_DedOn,1)>0,J11,0),IF(AND(COUNTIFS(WL_Space,C11,WL_Wall,E11,WL_Dup,0)=1,COUNTIFS(WL_Space,C11,WL_Wall,E11,WL_DedOn,1)=1),J11,0)))) | P11: =IF(OR(W11=0,J11=""),"",IF(OR(M11<>"نعم",C11="",E11=""),0,J11*SUMIFS(PL_FacesEff,PL_Space,C11,PL_Wall,E11))) | Q11: =IF(W11=0,"",IF(OR(N11<>"نعم",C11=""),0,IF(COUNTIFS(LN_Space,C11,LN_AutoEff,1)>0,U11,0))) | T11: =IF(W11=0,"",IF(B11="","ناقص بيانات: كود الفتحة",IF(V11=1,"تكرار كود الفتحة — غير محتسب",IF(C11="","ناقص بيانات: كود الفراغ",IF(COUNTIF(SpaceCodes,C11)=0,"ناقص بيانات: الفراغ غير مسجل",IF(E11="","ناقص بيانات: كود الحائط",IF(J11="","ناقص قياس",IF(AND(K11="",M11="",N11=""),"ناقص بيانات: حدد خيارات الخصم (نعم/لا)",IF(AND(K11="نعم",N(O11)=0,L11="",COUNTIFS(WL_Space,C11,WL_Wall,E11,WL_Dup,0)>1),"تنبيه خصم: للحائط أكثر من خامة — حدد الخامة المخصوم منها",IF(AND(K11="نعم",N(O11)=0,IF(L11="",COUNTIFS(WL_Space,C11,WL_Wall,E11,WL_Dup,0),COUNTIFS(WL_Space,C11,WL_Wall,E11,WL_Mat,L11,WL_Dup,0))>0),"تنبيه خصم: خصم الفتحات موقوف («لا») في سجل الحائط",IF(AND(K11="نعم",N(O11)=0),"تنبيه خصم: الحائط/الخامة غير مسجلة في حصر الحوائط",IF(AND(M11="نعم",N(P11)=0),"تنبيه خصم: الحائط غير مسجل في حصر اللياسة",IF(AND(N11="نعم",N(Q11)=0),"تنبيه خصم: لا يوجد سجل وزرات بخصم تلقائي للفراغ",IF(R11="نعم","يحتاج مراجعة","مكتمل")))))))))))))) | U11: =IF(OR(W11=0,V11=1,G11=""),0,G11*IF(I11="",1,I11)) -> 0 | V11: =IF(B11="",0,IF(SUMPRODUCT(--(B$4:B11=B11))>1,1,0)) -> 0 | W11: =IF(COUNTA(B11:C11,E11:I11,K11:N11)=0,0,1) -> 0
A12: 9 | D12: =IF(C12="","",IFERROR(INDEX(SpaceNames,MATCH(C12,SpaceCodes,0))&"","")) | J12: =IF(W12=0,"",IF(V12=1,0,IF(AND(G12<>"",H12<>""),G12*H12*IF(I12="",1,I12),""))) | O12: =IF(OR(W12=0,J12=""),"",IF(OR(K12<>"نعم",C12="",E12=""),0,IF(L12<>"",IF(COUNTIFS(WL_Space,C12,WL_Wall,E12,WL_Mat,L12,WL_DedOn,1)>0,J12,0),IF(AND(COUNTIFS(WL_Space,C12,WL_Wall,E12,WL_Dup,0)=1,COUNTIFS(WL_Space,C12,WL_Wall,E12,WL_DedOn,1)=1),J12,0)))) | P12: =IF(OR(W12=0,J12=""),"",IF(OR(M12<>"نعم",C12="",E12=""),0,J12*SUMIFS(PL_FacesEff,PL_Space,C12,PL_Wall,E12))) | Q12: =IF(W12=0,"",IF(OR(N12<>"نعم",C12=""),0,IF(COUNTIFS(LN_Space,C12,LN_AutoEff,1)>0,U12,0))) | T12: =IF(W12=0,"",IF(B12="","ناقص بيانات: كود الفتحة",IF(V12=1,"تكرار كود الفتحة — غير محتسب",IF(C12="","ناقص بيانات: كود الفراغ",IF(COUNTIF(SpaceCodes,C12)=0,"ناقص بيانات: الفراغ غير مسجل",IF(E12="","ناقص بيانات: كود الحائط",IF(J12="","ناقص قياس",IF(AND(K12="",M12="",N12=""),"ناقص بيانات: حدد خيارات الخصم (نعم/لا)",IF(AND(K12="نعم",N(O12)=0,L12="",COUNTIFS(WL_Space,C12,WL_Wall,E12,WL_Dup,0)>1),"تنبيه خصم: للحائط أكثر من خامة — حدد الخامة المخصوم منها",IF(AND(K12="نعم",N(O12)=0,IF(L12="",COUNTIFS(WL_Space,C12,WL_Wall,E12,WL_Dup,0),COUNTIFS(WL_Space,C12,WL_Wall,E12,WL_Mat,L12,WL_Dup,0))>0),"تنبيه خصم: خصم الفتحات موقوف («لا») في سجل الحائط",IF(AND(K12="نعم",N(O12)=0),"تنبيه خصم: الحائط/الخامة غير مسجلة في حصر الحوائط",IF(AND(M12="نعم",N(P12)=0),"تنبيه خصم: الحائط غير مسجل في حصر اللياسة",IF(AND(N12="نعم",N(Q12)=0),"تنبيه خصم: لا يوجد سجل وزرات بخصم تلقائي للفراغ",IF(R12="نعم","يحتاج مراجعة","مكتمل")))))))))))))) | U12: =IF(OR(W12=0,V12=1,G12=""),0,G12*IF(I12="",1,I12)) -> 0 | V12: =IF(B12="",0,IF(SUMPRODUCT(--(B$4:B12=B12))>1,1,0)) -> 0 | W12: =IF(COUNTA(B12:C12,E12:I12,K12:N12)=0,0,1) -> 0
A13: 10 | D13: =IF(C13="","",IFERROR(INDEX(SpaceNames,MATCH(C13,SpaceCodes,0))&"","")) | J13: =IF(W13=0,"",IF(V13=1,0,IF(AND(G13<>"",H13<>""),G13*H13*IF(I13="",1,I13),""))) | O13: =IF(OR(W13=0,J13=""),"",IF(OR(K13<>"نعم",C13="",E13=""),0,IF(L13<>"",IF(COUNTIFS(WL_Space,C13,WL_Wall,E13,WL_Mat,L13,WL_DedOn,1)>0,J13,0),IF(AND(COUNTIFS(WL_Space,C13,WL_Wall,E13,WL_Dup,0)=1,COUNTIFS(WL_Space,C13,WL_Wall,E13,WL_DedOn,1)=1),J13,0)))) | P13: =IF(OR(W13=0,J13=""),"",IF(OR(M13<>"نعم",C13="",E13=""),0,J13*SUMIFS(PL_FacesEff,PL_Space,C13,PL_Wall,E13))) | Q13: =IF(W13=0,"",IF(OR(N13<>"نعم",C13=""),0,IF(COUNTIFS(LN_Space,C13,LN_AutoEff,1)>0,U13,0))) | T13: =IF(W13=0,"",IF(B13="","ناقص بيانات: كود الفتحة",IF(V13=1,"تكرار كود الفتحة — غير محتسب",IF(C13="","ناقص بيانات: كود الفراغ",IF(COUNTIF(SpaceCodes,C13)=0,"ناقص بيانات: الفراغ غير مسجل",IF(E13="","ناقص بيانات: كود الحائط",IF(J13="","ناقص قياس",IF(AND(K13="",M13="",N13=""),"ناقص بيانات: حدد خيارات الخصم (نعم/لا)",IF(AND(K13="نعم",N(O13)=0,L13="",COUNTIFS(WL_Space,C13,WL_Wall,E13,WL_Dup,0)>1),"تنبيه خصم: للحائط أكثر من خامة — حدد الخامة المخصوم منها",IF(AND(K13="نعم",N(O13)=0,IF(L13="",COUNTIFS(WL_Space,C13,WL_Wall,E13,WL_Dup,0),COUNTIFS(WL_Space,C13,WL_Wall,E13,WL_Mat,L13,WL_Dup,0))>0),"تنبيه خصم: خصم الفتحات موقوف («لا») في سجل الحائط",IF(AND(K13="نعم",N(O13)=0),"تنبيه خصم: الحائط/الخامة غير مسجلة في حصر الحوائط",IF(AND(M13="نعم",N(P13)=0),"تنبيه خصم: الحائط غير مسجل في حصر اللياسة",IF(AND(N13="نعم",N(Q13)=0),"تنبيه خصم: لا يوجد سجل وزرات بخصم تلقائي للفراغ",IF(R13="نعم","يحتاج مراجعة","مكتمل")))))))))))))) | U13: =IF(OR(W13=0,V13=1,G13=""),0,G13*IF(I13="",1,I13)) -> 0 | V13: =IF(B13="",0,IF(SUMPRODUCT(--(B$4:B13=B13))>1,1,0)) -> 0 | W13: =IF(COUNTA(B13:C13,E13:I13,K13:N13)=0,0,1) -> 0
A14: 11 | D14: =IF(C14="","",IFERROR(INDEX(SpaceNames,MATCH(C14,SpaceCodes,0))&"","")) | J14: =IF(W14=0,"",IF(V14=1,0,IF(AND(G14<>"",H14<>""),G14*H14*IF(I14="",1,I14),""))) | O14: =IF(OR(W14=0,J14=""),"",IF(OR(K14<>"نعم",C14="",E14=""),0,IF(L14<>"",IF(COUNTIFS(WL_Space,C14,WL_Wall,E14,WL_Mat,L14,WL_DedOn,1)>0,J14,0),IF(AND(COUNTIFS(WL_Space,C14,WL_Wall,E14,WL_Dup,0)=1,COUNTIFS(WL_Space,C14,WL_Wall,E14,WL_DedOn,1)=1),J14,0)))) | P14: =IF(OR(W14=0,J14=""),"",IF(OR(M14<>"نعم",C14="",E14=""),0,J14*SUMIFS(PL_FacesEff,PL_Space,C14,PL_Wall,E14))) | Q14: =IF(W14=0,"",IF(OR(N14<>"نعم",C14=""),0,IF(COUNTIFS(LN_Space,C14,LN_AutoEff,1)>0,U14,0))) | T14: =IF(W14=0,"",IF(B14="","ناقص بيانات: كود الفتحة",IF(V14=1,"تكرار كود الفتحة — غير محتسب",IF(C14="","ناقص بيانات: كود الفراغ",IF(COUNTIF(SpaceCodes,C14)=0,"ناقص بيانات: الفراغ غير مسجل",IF(E14="","ناقص بيانات: كود الحائط",IF(J14="","ناقص قياس",IF(AND(K14="",M14="",N14=""),"ناقص بيانات: حدد خيارات الخصم (نعم/لا)",IF(AND(K14="نعم",N(O14)=0,L14="",COUNTIFS(WL_Space,C14,WL_Wall,E14,WL_Dup,0)>1),"تنبيه خصم: للحائط أكثر من خامة — حدد الخامة المخصوم منها",IF(AND(K14="نعم",N(O14)=0,IF(L14="",COUNTIFS(WL_Space,C14,WL_Wall,E14,WL_Dup,0),COUNTIFS(WL_Space,C14,WL_Wall,E14,WL_Mat,L14,WL_Dup,0))>0),"تنبيه خصم: خصم الفتحات موقوف («لا») في سجل الحائط",IF(AND(K14="نعم",N(O14)=0),"تنبيه خصم: الحائط/الخامة غير مسجلة في حصر الحوائط",IF(AND(M14="نعم",N(P14)=0),"تنبيه خصم: الحائط غير مسجل في حصر اللياسة",IF(AND(N14="نعم",N(Q14)=0),"تنبيه خصم: لا يوجد سجل وزرات بخصم تلقائي للفراغ",IF(R14="نعم","يحتاج مراجعة","مكتمل")))))))))))))) | U14: =IF(OR(W14=0,V14=1,G14=""),0,G14*IF(I14="",1,I14)) -> 0 | V14: =IF(B14="",0,IF(SUMPRODUCT(--(B$4:B14=B14))>1,1,0)) -> 0 | W14: =IF(COUNTA(B14:C14,E14:I14,K14:N14)=0,0,1) -> 0
